2025-07-08 02:47:23,948 INFO    MainThread:164079 [wandb_setup.py:_flush():81] Current SDK version is 0.20.1
2025-07-08 02:47:23,949 INFO    MainThread:164079 [wandb_setup.py:_flush():81] Configure stats pid to 164079
2025-07-08 02:47:23,949 INFO    MainThread:164079 [wandb_setup.py:_flush():81] Loading settings from /home/qrbao/.config/wandb/settings
2025-07-08 02:47:23,949 INFO    MainThread:164079 [wandb_setup.py:_flush():81] Loading settings from /home/qrbao/Documents/code4/rllib/mycode/wandb/settings
2025-07-08 02:47:23,949 INFO    MainThread:164079 [wandb_setup.py:_flush():81] Loading settings from environment variables
2025-07-08 02:47:23,949 INFO    MainThread:164079 [wandb_init.py:setup_run_log_directory():703] Logging user logs to /home/qrbao/Documents/code4/rllib/mycode/wandb/run-20250708_024723-rf890yu5/logs/debug.log
2025-07-08 02:47:23,949 INFO    MainThread:164079 [wandb_init.py:setup_run_log_directory():704] Logging internal logs to /home/qrbao/Documents/code4/rllib/mycode/wandb/run-20250708_024723-rf890yu5/logs/debug-internal.log
2025-07-08 02:47:23,949 INFO    MainThread:164079 [wandb_init.py:monkeypatch_ipython():622] configuring jupyter hooks <wandb.sdk.wandb_init._WandbInit object at 0x72efb85140d0>
2025-07-08 02:47:23,950 INFO    MainThread:164079 [wandb_init.py:init():831] calling init triggers
2025-07-08 02:47:23,950 INFO    MainThread:164079 [wandb_init.py:init():836] wandb.init called with sweep_config: {}
config: {'algo': 'PPO', 'enable_new_api_stack': True, 'framework': 'torch', 'env': None, 'num_env_runners': None, 'num_envs_per_env_runner': None, 'num_agents': 4, 'evaluation_num_env_runners': 0, 'evaluation_interval': 0, 'evaluation_duration': 10, 'evaluation_duration_unit': 'episodes', 'evaluation_parallel_to_training': False, 'output': None, 'log_level': None, 'no_tune': False, 'num_samples': 1, 'max_concurrent_trials': None, 'verbose': 2, 'checkpoint_freq': 1, 'checkpoint_at_end': True, 'wandb_key': 'fdd7656f474bba144dea1887bcdab534bc7df647', 'wandb_project': 'waterworld-v4', 'wandb_run_name': None, 'stop_reward': 200.0, 'stop_iters': 200, 'stop_timesteps': 1000000, 'as_test': False, 'as_release_test': False, 'num_learners': None, 'num_cpus_per_learner': None, 'num_gpus_per_learner': None, 'num_aggregator_actors_per_learner': None, 'num_cpus': 0, 'local_mode': False, 'num_gpus': None, 'n_predators': 2, 'n_preys': 2, 'use_onnx_for_inference': False, 'explore_during_inference': False, 'num_episodes_during_inference': 10, '_wandb': {}}
2025-07-08 02:47:23,950 INFO    MainThread:164079 [wandb_init.py:init():872] starting backend
2025-07-08 02:47:24,156 INFO    MainThread:164079 [wandb_init.py:init():875] sending inform_init request
2025-07-08 02:47:24,158 INFO    MainThread:164079 [wandb_init.py:init():883] backend started and connected
2025-07-08 02:47:24,159 INFO    MainThread:164079 [wandb_run.py:_label_probe_notebook():1299] probe notebook
2025-07-08 02:47:24,177 INFO    MainThread:164079 [wandb_init.py:init():956] updated telemetry
2025-07-08 02:47:24,180 INFO    MainThread:164079 [wandb_init.py:init():980] communicating run to backend with 90.0 second timeout
2025-07-08 02:47:24,828 INFO    MainThread:164079 [wandb_init.py:init():1032] starting run threads in backend
2025-07-08 02:47:24,903 INFO    MainThread:164079 [wandb_run.py:_console_start():2453] atexit reg
2025-07-08 02:47:24,904 INFO    MainThread:164079 [wandb_run.py:_redirect():2301] redirect: wrap_raw
2025-07-08 02:47:24,904 INFO    MainThread:164079 [wandb_run.py:_redirect():2370] Wrapping output streams.
2025-07-08 02:47:24,904 INFO    MainThread:164079 [wandb_run.py:_redirect():2393] Redirects installed.
2025-07-08 02:47:24,904 INFO    MainThread:164079 [wandb_init.py:init():1078] run started, returning control to user process
2025-07-08 02:47:24,905 INFO    MainThread:164079 [wandb_init.py:_post_run_cell_hook():592] [no run ID] resuming backend
2025-07-08 02:47:24,909 INFO    MainThread:164079 [jupyter.py:save_ipynb():404] [no run ID] not saving jupyter notebook
2025-07-08 02:47:24,909 INFO    MainThread:164079 [wandb_init.py:_pre_run_cell_hook():581] [no run ID] pausing backend
2025-07-08 02:47:24,910 INFO    MainThread:164079 [wandb_init.py:_post_run_cell_hook():592] [no run ID] resuming backend
2025-07-08 02:47:24,914 INFO    MainThread:164079 [jupyter.py:save_ipynb():404] [no run ID] not saving jupyter notebook
2025-07-08 02:47:24,914 INFO    MainThread:164079 [wandb_init.py:_pre_run_cell_hook():581] [no run ID] pausing backend
2025-07-08 02:47:24,918 INFO    MainThread:164079 [wandb_init.py:_post_run_cell_hook():592] [no run ID] resuming backend
2025-07-08 02:47:24,921 INFO    MainThread:164079 [jupyter.py:save_ipynb():404] [no run ID] not saving jupyter notebook
2025-07-08 02:47:24,922 INFO    MainThread:164079 [wandb_init.py:_pre_run_cell_hook():581] [no run ID] pausing backend
2025-07-08 02:47:24,922 INFO    MainThread:164079 [wandb_init.py:_post_run_cell_hook():592] [no run ID] resuming backend
2025-07-08 02:47:24,926 INFO    MainThread:164079 [jupyter.py:save_ipynb():404] [no run ID] not saving jupyter notebook
2025-07-08 02:47:24,926 INFO    MainThread:164079 [wandb_init.py:_pre_run_cell_hook():581] [no run ID] pausing backend
2025-07-08 02:47:24,945 INFO    MainThread:164079 [wandb_init.py:_post_run_cell_hook():592] [no run ID] resuming backend
2025-07-08 02:47:24,948 INFO    MainThread:164079 [jupyter.py:save_ipynb():404] [no run ID] not saving jupyter notebook
2025-07-08 02:47:24,948 INFO    MainThread:164079 [wandb_init.py:_pre_run_cell_hook():581] [no run ID] pausing backend
2025-07-08 02:50:02,816 WARNING MsgRouterThr:164079 [router.py:message_loop():63] [no run ID] message_loop has been closed
Traceback (most recent call last):
  File "/home/qrbao/anaconda3/envs/rllib/lib/python3.10/site-packages/wandb/sdk/interface/router_sock.py", line 27, in _read_message
    return self._sock_client.read_server_response(timeout=1)
  File "/home/qrbao/anaconda3/envs/rllib/lib/python3.10/site-packages/wandb/sdk/lib/sock_client.py", line 235, in read_server_response
    data = self._read_packet_bytes(timeout=timeout)
  File "/home/qrbao/anaconda3/envs/rllib/lib/python3.10/site-packages/wandb/sdk/lib/sock_client.py", line 220, in _read_packet_bytes
    raise SockClientClosedError
wandb.sdk.lib.sock_client.SockClientClosedError

The above exception was the direct cause of the following exception:

Traceback (most recent call last):
  File "/home/qrbao/anaconda3/envs/rllib/lib/python3.10/site-packages/wandb/sdk/interface/router.py", line 56, in message_loop
    msg = self._read_message()
  File "/home/qrbao/anaconda3/envs/rllib/lib/python3.10/site-packages/wandb/sdk/interface/router_sock.py", line 29, in _read_message
    raise MessageRouterClosedError from e
wandb.sdk.interface.router.MessageRouterClosedError
2025-07-08 02:50:02,821 INFO    MsgRouterThr:164079 [mailbox.py:close():129] [no run ID] Closing mailbox, abandoning 1 handles.
2025-07-08 02:50:02,852 ERROR   MainThread:164079 [redirect.py:_on_write():664] [no run ID] error in stderr callback
Traceback (most recent call last):
  File "/home/qrbao/anaconda3/envs/rllib/lib/python3.10/site-packages/wandb/sdk/lib/redirect.py", line 662, in _on_write
    cb(written_data)
  File "/home/qrbao/anaconda3/envs/rllib/lib/python3.10/site-packages/wandb/sdk/wandb_run.py", line 2380, in <lambda>
    lambda data: self._console_raw_callback("stderr", data),
  File "/home/qrbao/anaconda3/envs/rllib/lib/python3.10/site-packages/wandb/sdk/wandb_run.py", line 391, in wrapper
    return func(self, *args, **kwargs)
  File "/home/qrbao/anaconda3/envs/rllib/lib/python3.10/site-packages/wandb/sdk/wandb_run.py", line 449, in wrapper_fn
    return func(self, *args, **kwargs)
  File "/home/qrbao/anaconda3/envs/rllib/lib/python3.10/site-packages/wandb/sdk/wandb_run.py", line 1561, in _console_raw_callback
    self._backend.interface.publish_output_raw(name, data)
  File "/home/qrbao/anaconda3/envs/rllib/lib/python3.10/site-packages/wandb/sdk/interface/interface.py", line 772, in publish_output_raw
    self._publish_output_raw(o)
  File "/home/qrbao/anaconda3/envs/rllib/lib/python3.10/site-packages/wandb/sdk/interface/interface_shared.py", line 38, in _publish_output_raw
    self._publish(rec)
  File "/home/qrbao/anaconda3/envs/rllib/lib/python3.10/site-packages/wandb/sdk/interface/interface_sock.py", line 39, in _publish
    self._sock_client.send_record_publish(record)
  File "/home/qrbao/anaconda3/envs/rllib/lib/python3.10/site-packages/wandb/sdk/lib/sock_client.py", line 174, in send_record_publish
    self.send_server_request(server_req)
  File "/home/qrbao/anaconda3/envs/rllib/lib/python3.10/site-packages/wandb/sdk/lib/sock_client.py", line 154, in send_server_request
    self._send_message(msg)
  File "/home/qrbao/anaconda3/envs/rllib/lib/python3.10/site-packages/wandb/sdk/lib/sock_client.py", line 151, in _send_message
    self._sendall_with_error_handle(header + data)
  File "/home/qrbao/anaconda3/envs/rllib/lib/python3.10/site-packages/wandb/sdk/lib/sock_client.py", line 130, in _sendall_with_error_handle
    sent = self._sock.send(data)
BrokenPipeError: [Errno 32] Broken pipe
2025-07-08 02:50:02,854 ERROR   MainThread:164079 [redirect.py:_on_write():664] [no run ID] error in stdout callback
Traceback (most recent call last):
  File "/home/qrbao/anaconda3/envs/rllib/lib/python3.10/site-packages/wandb/sdk/lib/redirect.py", line 662, in _on_write
    cb(written_data)
  File "/home/qrbao/anaconda3/envs/rllib/lib/python3.10/site-packages/wandb/sdk/wandb_run.py", line 2374, in <lambda>
    lambda data: self._console_raw_callback("stdout", data),
  File "/home/qrbao/anaconda3/envs/rllib/lib/python3.10/site-packages/wandb/sdk/wandb_run.py", line 391, in wrapper
    return func(self, *args, **kwargs)
  File "/home/qrbao/anaconda3/envs/rllib/lib/python3.10/site-packages/wandb/sdk/wandb_run.py", line 449, in wrapper_fn
    return func(self, *args, **kwargs)
  File "/home/qrbao/anaconda3/envs/rllib/lib/python3.10/site-packages/wandb/sdk/wandb_run.py", line 1561, in _console_raw_callback
    self._backend.interface.publish_output_raw(name, data)
  File "/home/qrbao/anaconda3/envs/rllib/lib/python3.10/site-packages/wandb/sdk/interface/interface.py", line 772, in publish_output_raw
    self._publish_output_raw(o)
  File "/home/qrbao/anaconda3/envs/rllib/lib/python3.10/site-packages/wandb/sdk/interface/interface_shared.py", line 38, in _publish_output_raw
    self._publish(rec)
  File "/home/qrbao/anaconda3/envs/rllib/lib/python3.10/site-packages/wandb/sdk/interface/interface_sock.py", line 39, in _publish
    self._sock_client.send_record_publish(record)
  File "/home/qrbao/anaconda3/envs/rllib/lib/python3.10/site-packages/wandb/sdk/lib/sock_client.py", line 174, in send_record_publish
    self.send_server_request(server_req)
  File "/home/qrbao/anaconda3/envs/rllib/lib/python3.10/site-packages/wandb/sdk/lib/sock_client.py", line 154, in send_server_request
    self._send_message(msg)
  File "/home/qrbao/anaconda3/envs/rllib/lib/python3.10/site-packages/wandb/sdk/lib/sock_client.py", line 151, in _send_message
    self._sendall_with_error_handle(header + data)
  File "/home/qrbao/anaconda3/envs/rllib/lib/python3.10/site-packages/wandb/sdk/lib/sock_client.py", line 130, in _sendall_with_error_handle
    sent = self._sock.send(data)
BrokenPipeError: [Errno 32] Broken pipe
2025-07-08 02:50:02,854 ERROR   MainThread:164079 [redirect.py:_on_write():664] [no run ID] error in stdout callback
Traceback (most recent call last):
  File "/home/qrbao/anaconda3/envs/rllib/lib/python3.10/site-packages/wandb/sdk/lib/redirect.py", line 662, in _on_write
    cb(written_data)
  File "/home/qrbao/anaconda3/envs/rllib/lib/python3.10/site-packages/wandb/sdk/wandb_run.py", line 2374, in <lambda>
    lambda data: self._console_raw_callback("stdout", data),
  File "/home/qrbao/anaconda3/envs/rllib/lib/python3.10/site-packages/wandb/sdk/wandb_run.py", line 391, in wrapper
    return func(self, *args, **kwargs)
  File "/home/qrbao/anaconda3/envs/rllib/lib/python3.10/site-packages/wandb/sdk/wandb_run.py", line 449, in wrapper_fn
    return func(self, *args, **kwargs)
  File "/home/qrbao/anaconda3/envs/rllib/lib/python3.10/site-packages/wandb/sdk/wandb_run.py", line 1561, in _console_raw_callback
    self._backend.interface.publish_output_raw(name, data)
  File "/home/qrbao/anaconda3/envs/rllib/lib/python3.10/site-packages/wandb/sdk/interface/interface.py", line 772, in publish_output_raw
    self._publish_output_raw(o)
  File "/home/qrbao/anaconda3/envs/rllib/lib/python3.10/site-packages/wandb/sdk/interface/interface_shared.py", line 38, in _publish_output_raw
    self._publish(rec)
  File "/home/qrbao/anaconda3/envs/rllib/lib/python3.10/site-packages/wandb/sdk/interface/interface_sock.py", line 39, in _publish
    self._sock_client.send_record_publish(record)
  File "/home/qrbao/anaconda3/envs/rllib/lib/python3.10/site-packages/wandb/sdk/lib/sock_client.py", line 174, in send_record_publish
    self.send_server_request(server_req)
  File "/home/qrbao/anaconda3/envs/rllib/lib/python3.10/site-packages/wandb/sdk/lib/sock_client.py", line 154, in send_server_request
    self._send_message(msg)
  File "/home/qrbao/anaconda3/envs/rllib/lib/python3.10/site-packages/wandb/sdk/lib/sock_client.py", line 151, in _send_message
    self._sendall_with_error_handle(header + data)
  File "/home/qrbao/anaconda3/envs/rllib/lib/python3.10/site-packages/wandb/sdk/lib/sock_client.py", line 130, in _sendall_with_error_handle
    sent = self._sock.send(data)
BrokenPipeError: [Errno 32] Broken pipe
2025-07-08 03:20:03,951 ERROR   MainThread:164079 [redirect.py:_on_write():664] [no run ID] error in stderr callback
Traceback (most recent call last):
  File "/home/qrbao/anaconda3/envs/rllib/lib/python3.10/site-packages/wandb/sdk/lib/redirect.py", line 662, in _on_write
    cb(written_data)
  File "/home/qrbao/anaconda3/envs/rllib/lib/python3.10/site-packages/wandb/sdk/wandb_run.py", line 2380, in <lambda>
    lambda data: self._console_raw_callback("stderr", data),
  File "/home/qrbao/anaconda3/envs/rllib/lib/python3.10/site-packages/wandb/sdk/wandb_run.py", line 391, in wrapper
    return func(self, *args, **kwargs)
  File "/home/qrbao/anaconda3/envs/rllib/lib/python3.10/site-packages/wandb/sdk/wandb_run.py", line 449, in wrapper_fn
    return func(self, *args, **kwargs)
  File "/home/qrbao/anaconda3/envs/rllib/lib/python3.10/site-packages/wandb/sdk/wandb_run.py", line 1561, in _console_raw_callback
    self._backend.interface.publish_output_raw(name, data)
  File "/home/qrbao/anaconda3/envs/rllib/lib/python3.10/site-packages/wandb/sdk/interface/interface.py", line 772, in publish_output_raw
    self._publish_output_raw(o)
  File "/home/qrbao/anaconda3/envs/rllib/lib/python3.10/site-packages/wandb/sdk/interface/interface_shared.py", line 38, in _publish_output_raw
    self._publish(rec)
  File "/home/qrbao/anaconda3/envs/rllib/lib/python3.10/site-packages/wandb/sdk/interface/interface_sock.py", line 39, in _publish
    self._sock_client.send_record_publish(record)
  File "/home/qrbao/anaconda3/envs/rllib/lib/python3.10/site-packages/wandb/sdk/lib/sock_client.py", line 174, in send_record_publish
    self.send_server_request(server_req)
  File "/home/qrbao/anaconda3/envs/rllib/lib/python3.10/site-packages/wandb/sdk/lib/sock_client.py", line 154, in send_server_request
    self._send_message(msg)
  File "/home/qrbao/anaconda3/envs/rllib/lib/python3.10/site-packages/wandb/sdk/lib/sock_client.py", line 151, in _send_message
    self._sendall_with_error_handle(header + data)
  File "/home/qrbao/anaconda3/envs/rllib/lib/python3.10/site-packages/wandb/sdk/lib/sock_client.py", line 130, in _sendall_with_error_handle
    sent = self._sock.send(data)
BrokenPipeError: [Errno 32] Broken pipe
2025-07-08 03:20:03,953 ERROR   MainThread:164079 [redirect.py:_on_write():664] [no run ID] error in stderr callback
Traceback (most recent call last):
  File "/home/qrbao/anaconda3/envs/rllib/lib/python3.10/site-packages/wandb/sdk/lib/redirect.py", line 662, in _on_write
    cb(written_data)
  File "/home/qrbao/anaconda3/envs/rllib/lib/python3.10/site-packages/wandb/sdk/wandb_run.py", line 2380, in <lambda>
    lambda data: self._console_raw_callback("stderr", data),
  File "/home/qrbao/anaconda3/envs/rllib/lib/python3.10/site-packages/wandb/sdk/wandb_run.py", line 391, in wrapper
    return func(self, *args, **kwargs)
  File "/home/qrbao/anaconda3/envs/rllib/lib/python3.10/site-packages/wandb/sdk/wandb_run.py", line 449, in wrapper_fn
    return func(self, *args, **kwargs)
  File "/home/qrbao/anaconda3/envs/rllib/lib/python3.10/site-packages/wandb/sdk/wandb_run.py", line 1561, in _console_raw_callback
    self._backend.interface.publish_output_raw(name, data)
  File "/home/qrbao/anaconda3/envs/rllib/lib/python3.10/site-packages/wandb/sdk/interface/interface.py", line 772, in publish_output_raw
    self._publish_output_raw(o)
  File "/home/qrbao/anaconda3/envs/rllib/lib/python3.10/site-packages/wandb/sdk/interface/interface_shared.py", line 38, in _publish_output_raw
    self._publish(rec)
  File "/home/qrbao/anaconda3/envs/rllib/lib/python3.10/site-packages/wandb/sdk/interface/interface_sock.py", line 39, in _publish
    self._sock_client.send_record_publish(record)
  File "/home/qrbao/anaconda3/envs/rllib/lib/python3.10/site-packages/wandb/sdk/lib/sock_client.py", line 174, in send_record_publish
    self.send_server_request(server_req)
  File "/home/qrbao/anaconda3/envs/rllib/lib/python3.10/site-packages/wandb/sdk/lib/sock_client.py", line 154, in send_server_request
    self._send_message(msg)
  File "/home/qrbao/anaconda3/envs/rllib/lib/python3.10/site-packages/wandb/sdk/lib/sock_client.py", line 151, in _send_message
    self._sendall_with_error_handle(header + data)
  File "/home/qrbao/anaconda3/envs/rllib/lib/python3.10/site-packages/wandb/sdk/lib/sock_client.py", line 130, in _sendall_with_error_handle
    sent = self._sock.send(data)
BrokenPipeError: [Errno 32] Broken pipe
2025-07-08 03:20:03,986 ERROR   MainThread:164079 [redirect.py:_on_write():664] [no run ID] error in stdout callback
Traceback (most recent call last):
  File "/home/qrbao/anaconda3/envs/rllib/lib/python3.10/site-packages/wandb/sdk/lib/redirect.py", line 662, in _on_write
    cb(written_data)
  File "/home/qrbao/anaconda3/envs/rllib/lib/python3.10/site-packages/wandb/sdk/wandb_run.py", line 2374, in <lambda>
    lambda data: self._console_raw_callback("stdout", data),
  File "/home/qrbao/anaconda3/envs/rllib/lib/python3.10/site-packages/wandb/sdk/wandb_run.py", line 391, in wrapper
    return func(self, *args, **kwargs)
  File "/home/qrbao/anaconda3/envs/rllib/lib/python3.10/site-packages/wandb/sdk/wandb_run.py", line 449, in wrapper_fn
    return func(self, *args, **kwargs)
  File "/home/qrbao/anaconda3/envs/rllib/lib/python3.10/site-packages/wandb/sdk/wandb_run.py", line 1561, in _console_raw_callback
    self._backend.interface.publish_output_raw(name, data)
  File "/home/qrbao/anaconda3/envs/rllib/lib/python3.10/site-packages/wandb/sdk/interface/interface.py", line 772, in publish_output_raw
    self._publish_output_raw(o)
  File "/home/qrbao/anaconda3/envs/rllib/lib/python3.10/site-packages/wandb/sdk/interface/interface_shared.py", line 38, in _publish_output_raw
    self._publish(rec)
  File "/home/qrbao/anaconda3/envs/rllib/lib/python3.10/site-packages/wandb/sdk/interface/interface_sock.py", line 39, in _publish
    self._sock_client.send_record_publish(record)
  File "/home/qrbao/anaconda3/envs/rllib/lib/python3.10/site-packages/wandb/sdk/lib/sock_client.py", line 174, in send_record_publish
    self.send_server_request(server_req)
  File "/home/qrbao/anaconda3/envs/rllib/lib/python3.10/site-packages/wandb/sdk/lib/sock_client.py", line 154, in send_server_request
    self._send_message(msg)
  File "/home/qrbao/anaconda3/envs/rllib/lib/python3.10/site-packages/wandb/sdk/lib/sock_client.py", line 151, in _send_message
    self._sendall_with_error_handle(header + data)
  File "/home/qrbao/anaconda3/envs/rllib/lib/python3.10/site-packages/wandb/sdk/lib/sock_client.py", line 130, in _sendall_with_error_handle
    sent = self._sock.send(data)
BrokenPipeError: [Errno 32] Broken pipe
2025-07-08 03:20:03,986 ERROR   MainThread:164079 [redirect.py:_on_write():664] [no run ID] error in stdout callback
Traceback (most recent call last):
  File "/home/qrbao/anaconda3/envs/rllib/lib/python3.10/site-packages/wandb/sdk/lib/redirect.py", line 662, in _on_write
    cb(written_data)
  File "/home/qrbao/anaconda3/envs/rllib/lib/python3.10/site-packages/wandb/sdk/wandb_run.py", line 2374, in <lambda>
    lambda data: self._console_raw_callback("stdout", data),
  File "/home/qrbao/anaconda3/envs/rllib/lib/python3.10/site-packages/wandb/sdk/wandb_run.py", line 391, in wrapper
    return func(self, *args, **kwargs)
  File "/home/qrbao/anaconda3/envs/rllib/lib/python3.10/site-packages/wandb/sdk/wandb_run.py", line 449, in wrapper_fn
    return func(self, *args, **kwargs)
  File "/home/qrbao/anaconda3/envs/rllib/lib/python3.10/site-packages/wandb/sdk/wandb_run.py", line 1561, in _console_raw_callback
    self._backend.interface.publish_output_raw(name, data)
  File "/home/qrbao/anaconda3/envs/rllib/lib/python3.10/site-packages/wandb/sdk/interface/interface.py", line 772, in publish_output_raw
    self._publish_output_raw(o)
  File "/home/qrbao/anaconda3/envs/rllib/lib/python3.10/site-packages/wandb/sdk/interface/interface_shared.py", line 38, in _publish_output_raw
    self._publish(rec)
  File "/home/qrbao/anaconda3/envs/rllib/lib/python3.10/site-packages/wandb/sdk/interface/interface_sock.py", line 39, in _publish
    self._sock_client.send_record_publish(record)
  File "/home/qrbao/anaconda3/envs/rllib/lib/python3.10/site-packages/wandb/sdk/lib/sock_client.py", line 174, in send_record_publish
    self.send_server_request(server_req)
  File "/home/qrbao/anaconda3/envs/rllib/lib/python3.10/site-packages/wandb/sdk/lib/sock_client.py", line 154, in send_server_request
    self._send_message(msg)
  File "/home/qrbao/anaconda3/envs/rllib/lib/python3.10/site-packages/wandb/sdk/lib/sock_client.py", line 151, in _send_message
    self._sendall_with_error_handle(header + data)
  File "/home/qrbao/anaconda3/envs/rllib/lib/python3.10/site-packages/wandb/sdk/lib/sock_client.py", line 130, in _sendall_with_error_handle
    sent = self._sock.send(data)
BrokenPipeError: [Errno 32] Broken pipe
2025-07-08 03:20:03,986 INFO    MainThread:164079 [wandb_init.py:_post_run_cell_hook():592] [no run ID] resuming backend
2025-07-08 03:20:03,987 ERROR   MainThread:164079 [redirect.py:_on_write():664] [no run ID] error in stdout callback
Traceback (most recent call last):
  File "/home/qrbao/anaconda3/envs/rllib/lib/python3.10/site-packages/IPython/core/events.py", line 82, in trigger
    func(*args, **kwargs)
  File "/home/qrbao/anaconda3/envs/rllib/lib/python3.10/site-packages/wandb/sdk/wandb_init.py", line 593, in _post_run_cell_hook
    self.backend.interface.publish_resume()
  File "/home/qrbao/anaconda3/envs/rllib/lib/python3.10/site-packages/wandb/sdk/interface/interface.py", line 788, in publish_resume
    self._publish_resume(resume)
  File "/home/qrbao/anaconda3/envs/rllib/lib/python3.10/site-packages/wandb/sdk/interface/interface_shared.py", line 293, in _publish_resume
    self._publish(rec)
  File "/home/qrbao/anaconda3/envs/rllib/lib/python3.10/site-packages/wandb/sdk/interface/interface_sock.py", line 39, in _publish
    self._sock_client.send_record_publish(record)
  File "/home/qrbao/anaconda3/envs/rllib/lib/python3.10/site-packages/wandb/sdk/lib/sock_client.py", line 174, in send_record_publish
    self.send_server_request(server_req)
  File "/home/qrbao/anaconda3/envs/rllib/lib/python3.10/site-packages/wandb/sdk/lib/sock_client.py", line 154, in send_server_request
    self._send_message(msg)
  File "/home/qrbao/anaconda3/envs/rllib/lib/python3.10/site-packages/wandb/sdk/lib/sock_client.py", line 151, in _send_message
    self._sendall_with_error_handle(header + data)
  File "/home/qrbao/anaconda3/envs/rllib/lib/python3.10/site-packages/wandb/sdk/lib/sock_client.py", line 130, in _sendall_with_error_handle
    sent = self._sock.send(data)
BrokenPipeError: [Errno 32] Broken pipe

During handling of the above exception, another exception occurred:

Traceback (most recent call last):
  File "/home/qrbao/anaconda3/envs/rllib/lib/python3.10/site-packages/wandb/sdk/lib/redirect.py", line 662, in _on_write
    cb(written_data)
  File "/home/qrbao/anaconda3/envs/rllib/lib/python3.10/site-packages/wandb/sdk/wandb_run.py", line 2374, in <lambda>
    lambda data: self._console_raw_callback("stdout", data),
  File "/home/qrbao/anaconda3/envs/rllib/lib/python3.10/site-packages/wandb/sdk/wandb_run.py", line 391, in wrapper
    return func(self, *args, **kwargs)
  File "/home/qrbao/anaconda3/envs/rllib/lib/python3.10/site-packages/wandb/sdk/wandb_run.py", line 449, in wrapper_fn
    return func(self, *args, **kwargs)
  File "/home/qrbao/anaconda3/envs/rllib/lib/python3.10/site-packages/wandb/sdk/wandb_run.py", line 1561, in _console_raw_callback
    self._backend.interface.publish_output_raw(name, data)
  File "/home/qrbao/anaconda3/envs/rllib/lib/python3.10/site-packages/wandb/sdk/interface/interface.py", line 772, in publish_output_raw
    self._publish_output_raw(o)
  File "/home/qrbao/anaconda3/envs/rllib/lib/python3.10/site-packages/wandb/sdk/interface/interface_shared.py", line 38, in _publish_output_raw
    self._publish(rec)
  File "/home/qrbao/anaconda3/envs/rllib/lib/python3.10/site-packages/wandb/sdk/interface/interface_sock.py", line 39, in _publish
    self._sock_client.send_record_publish(record)
  File "/home/qrbao/anaconda3/envs/rllib/lib/python3.10/site-packages/wandb/sdk/lib/sock_client.py", line 174, in send_record_publish
    self.send_server_request(server_req)
  File "/home/qrbao/anaconda3/envs/rllib/lib/python3.10/site-packages/wandb/sdk/lib/sock_client.py", line 154, in send_server_request
    self._send_message(msg)
  File "/home/qrbao/anaconda3/envs/rllib/lib/python3.10/site-packages/wandb/sdk/lib/sock_client.py", line 151, in _send_message
    self._sendall_with_error_handle(header + data)
  File "/home/qrbao/anaconda3/envs/rllib/lib/python3.10/site-packages/wandb/sdk/lib/sock_client.py", line 130, in _sendall_with_error_handle
    sent = self._sock.send(data)
BrokenPipeError: [Errno 32] Broken pipe
2025-07-08 03:20:03,992 ERROR   MainThread:164079 [redirect.py:_on_write():664] [no run ID] error in stdout callback
Traceback (most recent call last):
  File "/home/qrbao/anaconda3/envs/rllib/lib/python3.10/site-packages/IPython/core/events.py", line 82, in trigger
    func(*args, **kwargs)
  File "/home/qrbao/anaconda3/envs/rllib/lib/python3.10/site-packages/wandb/sdk/wandb_init.py", line 593, in _post_run_cell_hook
    self.backend.interface.publish_resume()
  File "/home/qrbao/anaconda3/envs/rllib/lib/python3.10/site-packages/wandb/sdk/interface/interface.py", line 788, in publish_resume
    self._publish_resume(resume)
  File "/home/qrbao/anaconda3/envs/rllib/lib/python3.10/site-packages/wandb/sdk/interface/interface_shared.py", line 293, in _publish_resume
    self._publish(rec)
  File "/home/qrbao/anaconda3/envs/rllib/lib/python3.10/site-packages/wandb/sdk/interface/interface_sock.py", line 39, in _publish
    self._sock_client.send_record_publish(record)
  File "/home/qrbao/anaconda3/envs/rllib/lib/python3.10/site-packages/wandb/sdk/lib/sock_client.py", line 174, in send_record_publish
    self.send_server_request(server_req)
  File "/home/qrbao/anaconda3/envs/rllib/lib/python3.10/site-packages/wandb/sdk/lib/sock_client.py", line 154, in send_server_request
    self._send_message(msg)
  File "/home/qrbao/anaconda3/envs/rllib/lib/python3.10/site-packages/wandb/sdk/lib/sock_client.py", line 151, in _send_message
    self._sendall_with_error_handle(header + data)
  File "/home/qrbao/anaconda3/envs/rllib/lib/python3.10/site-packages/wandb/sdk/lib/sock_client.py", line 130, in _sendall_with_error_handle
    sent = self._sock.send(data)
BrokenPipeError: [Errno 32] Broken pipe

During handling of the above exception, another exception occurred:

Traceback (most recent call last):
  File "/home/qrbao/anaconda3/envs/rllib/lib/python3.10/site-packages/wandb/sdk/lib/redirect.py", line 662, in _on_write
    cb(written_data)
  File "/home/qrbao/anaconda3/envs/rllib/lib/python3.10/site-packages/wandb/sdk/wandb_run.py", line 2374, in <lambda>
    lambda data: self._console_raw_callback("stdout", data),
  File "/home/qrbao/anaconda3/envs/rllib/lib/python3.10/site-packages/wandb/sdk/wandb_run.py", line 391, in wrapper
    return func(self, *args, **kwargs)
  File "/home/qrbao/anaconda3/envs/rllib/lib/python3.10/site-packages/wandb/sdk/wandb_run.py", line 449, in wrapper_fn
    return func(self, *args, **kwargs)
  File "/home/qrbao/anaconda3/envs/rllib/lib/python3.10/site-packages/wandb/sdk/wandb_run.py", line 1561, in _console_raw_callback
    self._backend.interface.publish_output_raw(name, data)
  File "/home/qrbao/anaconda3/envs/rllib/lib/python3.10/site-packages/wandb/sdk/interface/interface.py", line 772, in publish_output_raw
    self._publish_output_raw(o)
  File "/home/qrbao/anaconda3/envs/rllib/lib/python3.10/site-packages/wandb/sdk/interface/interface_shared.py", line 38, in _publish_output_raw
    self._publish(rec)
  File "/home/qrbao/anaconda3/envs/rllib/lib/python3.10/site-packages/wandb/sdk/interface/interface_sock.py", line 39, in _publish
    self._sock_client.send_record_publish(record)
  File "/home/qrbao/anaconda3/envs/rllib/lib/python3.10/site-packages/wandb/sdk/lib/sock_client.py", line 174, in send_record_publish
    self.send_server_request(server_req)
  File "/home/qrbao/anaconda3/envs/rllib/lib/python3.10/site-packages/wandb/sdk/lib/sock_client.py", line 154, in send_server_request
    self._send_message(msg)
  File "/home/qrbao/anaconda3/envs/rllib/lib/python3.10/site-packages/wandb/sdk/lib/sock_client.py", line 151, in _send_message
    self._sendall_with_error_handle(header + data)
  File "/home/qrbao/anaconda3/envs/rllib/lib/python3.10/site-packages/wandb/sdk/lib/sock_client.py", line 130, in _sendall_with_error_handle
    sent = self._sock.send(data)
BrokenPipeError: [Errno 32] Broken pipe
2025-07-09 14:55:41,004 ERROR   Thread-2 (_watch_pipe_fd):164079 [redirect.py:_on_write():664] [no run ID] error in stderr callback
Traceback (most recent call last):
  File "/home/qrbao/anaconda3/envs/rllib/lib/python3.10/site-packages/wandb/sdk/lib/redirect.py", line 662, in _on_write
    cb(written_data)
  File "/home/qrbao/anaconda3/envs/rllib/lib/python3.10/site-packages/wandb/sdk/wandb_run.py", line 2380, in <lambda>
    lambda data: self._console_raw_callback("stderr", data),
  File "/home/qrbao/anaconda3/envs/rllib/lib/python3.10/site-packages/wandb/sdk/wandb_run.py", line 391, in wrapper
    return func(self, *args, **kwargs)
  File "/home/qrbao/anaconda3/envs/rllib/lib/python3.10/site-packages/wandb/sdk/wandb_run.py", line 449, in wrapper_fn
    return func(self, *args, **kwargs)
  File "/home/qrbao/anaconda3/envs/rllib/lib/python3.10/site-packages/wandb/sdk/wandb_run.py", line 1561, in _console_raw_callback
    self._backend.interface.publish_output_raw(name, data)
  File "/home/qrbao/anaconda3/envs/rllib/lib/python3.10/site-packages/wandb/sdk/interface/interface.py", line 772, in publish_output_raw
    self._publish_output_raw(o)
  File "/home/qrbao/anaconda3/envs/rllib/lib/python3.10/site-packages/wandb/sdk/interface/interface_shared.py", line 38, in _publish_output_raw
    self._publish(rec)
  File "/home/qrbao/anaconda3/envs/rllib/lib/python3.10/site-packages/wandb/sdk/interface/interface_sock.py", line 39, in _publish
    self._sock_client.send_record_publish(record)
  File "/home/qrbao/anaconda3/envs/rllib/lib/python3.10/site-packages/wandb/sdk/lib/sock_client.py", line 174, in send_record_publish
    self.send_server_request(server_req)
  File "/home/qrbao/anaconda3/envs/rllib/lib/python3.10/site-packages/wandb/sdk/lib/sock_client.py", line 154, in send_server_request
    self._send_message(msg)
  File "/home/qrbao/anaconda3/envs/rllib/lib/python3.10/site-packages/wandb/sdk/lib/sock_client.py", line 151, in _send_message
    self._sendall_with_error_handle(header + data)
  File "/home/qrbao/anaconda3/envs/rllib/lib/python3.10/site-packages/wandb/sdk/lib/sock_client.py", line 130, in _sendall_with_error_handle
    sent = self._sock.send(data)
BrokenPipeError: [Errno 32] Broken pipe
2025-07-09 14:55:41,005 ERROR   Thread-2 (_watch_pipe_fd):164079 [redirect.py:_on_write():664] [no run ID] error in stderr callback
Traceback (most recent call last):
  File "/home/qrbao/anaconda3/envs/rllib/lib/python3.10/site-packages/wandb/sdk/lib/redirect.py", line 662, in _on_write
    cb(written_data)
  File "/home/qrbao/anaconda3/envs/rllib/lib/python3.10/site-packages/wandb/sdk/wandb_run.py", line 2380, in <lambda>
    lambda data: self._console_raw_callback("stderr", data),
  File "/home/qrbao/anaconda3/envs/rllib/lib/python3.10/site-packages/wandb/sdk/wandb_run.py", line 391, in wrapper
    return func(self, *args, **kwargs)
  File "/home/qrbao/anaconda3/envs/rllib/lib/python3.10/site-packages/wandb/sdk/wandb_run.py", line 449, in wrapper_fn
    return func(self, *args, **kwargs)
  File "/home/qrbao/anaconda3/envs/rllib/lib/python3.10/site-packages/wandb/sdk/wandb_run.py", line 1561, in _console_raw_callback
    self._backend.interface.publish_output_raw(name, data)
  File "/home/qrbao/anaconda3/envs/rllib/lib/python3.10/site-packages/wandb/sdk/interface/interface.py", line 772, in publish_output_raw
    self._publish_output_raw(o)
  File "/home/qrbao/anaconda3/envs/rllib/lib/python3.10/site-packages/wandb/sdk/interface/interface_shared.py", line 38, in _publish_output_raw
    self._publish(rec)
  File "/home/qrbao/anaconda3/envs/rllib/lib/python3.10/site-packages/wandb/sdk/interface/interface_sock.py", line 39, in _publish
    self._sock_client.send_record_publish(record)
  File "/home/qrbao/anaconda3/envs/rllib/lib/python3.10/site-packages/wandb/sdk/lib/sock_client.py", line 174, in send_record_publish
    self.send_server_request(server_req)
  File "/home/qrbao/anaconda3/envs/rllib/lib/python3.10/site-packages/wandb/sdk/lib/sock_client.py", line 154, in send_server_request
    self._send_message(msg)
  File "/home/qrbao/anaconda3/envs/rllib/lib/python3.10/site-packages/wandb/sdk/lib/sock_client.py", line 151, in _send_message
    self._sendall_with_error_handle(header + data)
  File "/home/qrbao/anaconda3/envs/rllib/lib/python3.10/site-packages/wandb/sdk/lib/sock_client.py", line 130, in _sendall_with_error_handle
    sent = self._sock.send(data)
BrokenPipeError: [Errno 32] Broken pipe
2025-07-09 14:55:41,006 ERROR   Thread-2 (_watch_pipe_fd):164079 [redirect.py:_on_write():664] [no run ID] error in stderr callback
Traceback (most recent call last):
  File "/home/qrbao/anaconda3/envs/rllib/lib/python3.10/site-packages/wandb/sdk/lib/redirect.py", line 662, in _on_write
    cb(written_data)
  File "/home/qrbao/anaconda3/envs/rllib/lib/python3.10/site-packages/wandb/sdk/wandb_run.py", line 2380, in <lambda>
    lambda data: self._console_raw_callback("stderr", data),
  File "/home/qrbao/anaconda3/envs/rllib/lib/python3.10/site-packages/wandb/sdk/wandb_run.py", line 391, in wrapper
    return func(self, *args, **kwargs)
  File "/home/qrbao/anaconda3/envs/rllib/lib/python3.10/site-packages/wandb/sdk/wandb_run.py", line 449, in wrapper_fn
    return func(self, *args, **kwargs)
  File "/home/qrbao/anaconda3/envs/rllib/lib/python3.10/site-packages/wandb/sdk/wandb_run.py", line 1561, in _console_raw_callback
    self._backend.interface.publish_output_raw(name, data)
  File "/home/qrbao/anaconda3/envs/rllib/lib/python3.10/site-packages/wandb/sdk/interface/interface.py", line 772, in publish_output_raw
    self._publish_output_raw(o)
  File "/home/qrbao/anaconda3/envs/rllib/lib/python3.10/site-packages/wandb/sdk/interface/interface_shared.py", line 38, in _publish_output_raw
    self._publish(rec)
  File "/home/qrbao/anaconda3/envs/rllib/lib/python3.10/site-packages/wandb/sdk/interface/interface_sock.py", line 39, in _publish
    self._sock_client.send_record_publish(record)
  File "/home/qrbao/anaconda3/envs/rllib/lib/python3.10/site-packages/wandb/sdk/lib/sock_client.py", line 174, in send_record_publish
    self.send_server_request(server_req)
  File "/home/qrbao/anaconda3/envs/rllib/lib/python3.10/site-packages/wandb/sdk/lib/sock_client.py", line 154, in send_server_request
    self._send_message(msg)
  File "/home/qrbao/anaconda3/envs/rllib/lib/python3.10/site-packages/wandb/sdk/lib/sock_client.py", line 151, in _send_message
    self._sendall_with_error_handle(header + data)
  File "/home/qrbao/anaconda3/envs/rllib/lib/python3.10/site-packages/wandb/sdk/lib/sock_client.py", line 130, in _sendall_with_error_handle
    sent = self._sock.send(data)
BrokenPipeError: [Errno 32] Broken pipe
2025-07-09 14:55:41,009 ERROR   MainThread:164079 [redirect.py:_on_write():664] [no run ID] error in stderr callback
Traceback (most recent call last):
  File "/home/qrbao/anaconda3/envs/rllib/lib/python3.10/site-packages/wandb/sdk/lib/redirect.py", line 662, in _on_write
    cb(written_data)
  File "/home/qrbao/anaconda3/envs/rllib/lib/python3.10/site-packages/wandb/sdk/wandb_run.py", line 2380, in <lambda>
    lambda data: self._console_raw_callback("stderr", data),
  File "/home/qrbao/anaconda3/envs/rllib/lib/python3.10/site-packages/wandb/sdk/wandb_run.py", line 391, in wrapper
    return func(self, *args, **kwargs)
  File "/home/qrbao/anaconda3/envs/rllib/lib/python3.10/site-packages/wandb/sdk/wandb_run.py", line 449, in wrapper_fn
    return func(self, *args, **kwargs)
  File "/home/qrbao/anaconda3/envs/rllib/lib/python3.10/site-packages/wandb/sdk/wandb_run.py", line 1561, in _console_raw_callback
    self._backend.interface.publish_output_raw(name, data)
  File "/home/qrbao/anaconda3/envs/rllib/lib/python3.10/site-packages/wandb/sdk/interface/interface.py", line 772, in publish_output_raw
    self._publish_output_raw(o)
  File "/home/qrbao/anaconda3/envs/rllib/lib/python3.10/site-packages/wandb/sdk/interface/interface_shared.py", line 38, in _publish_output_raw
    self._publish(rec)
  File "/home/qrbao/anaconda3/envs/rllib/lib/python3.10/site-packages/wandb/sdk/interface/interface_sock.py", line 39, in _publish
    self._sock_client.send_record_publish(record)
  File "/home/qrbao/anaconda3/envs/rllib/lib/python3.10/site-packages/wandb/sdk/lib/sock_client.py", line 174, in send_record_publish
    self.send_server_request(server_req)
  File "/home/qrbao/anaconda3/envs/rllib/lib/python3.10/site-packages/wandb/sdk/lib/sock_client.py", line 154, in send_server_request
    self._send_message(msg)
  File "/home/qrbao/anaconda3/envs/rllib/lib/python3.10/site-packages/wandb/sdk/lib/sock_client.py", line 151, in _send_message
    self._sendall_with_error_handle(header + data)
  File "/home/qrbao/anaconda3/envs/rllib/lib/python3.10/site-packages/wandb/sdk/lib/sock_client.py", line 130, in _sendall_with_error_handle
    sent = self._sock.send(data)
BrokenPipeError: [Errno 32] Broken pipe
2025-07-09 14:55:41,010 ERROR   MainThread:164079 [redirect.py:_on_write():664] [no run ID] error in stderr callback
Traceback (most recent call last):
  File "/home/qrbao/anaconda3/envs/rllib/lib/python3.10/site-packages/wandb/sdk/lib/redirect.py", line 662, in _on_write
    cb(written_data)
  File "/home/qrbao/anaconda3/envs/rllib/lib/python3.10/site-packages/wandb/sdk/wandb_run.py", line 2380, in <lambda>
    lambda data: self._console_raw_callback("stderr", data),
  File "/home/qrbao/anaconda3/envs/rllib/lib/python3.10/site-packages/wandb/sdk/wandb_run.py", line 391, in wrapper
    return func(self, *args, **kwargs)
  File "/home/qrbao/anaconda3/envs/rllib/lib/python3.10/site-packages/wandb/sdk/wandb_run.py", line 449, in wrapper_fn
    return func(self, *args, **kwargs)
  File "/home/qrbao/anaconda3/envs/rllib/lib/python3.10/site-packages/wandb/sdk/wandb_run.py", line 1561, in _console_raw_callback
    self._backend.interface.publish_output_raw(name, data)
  File "/home/qrbao/anaconda3/envs/rllib/lib/python3.10/site-packages/wandb/sdk/interface/interface.py", line 772, in publish_output_raw
    self._publish_output_raw(o)
  File "/home/qrbao/anaconda3/envs/rllib/lib/python3.10/site-packages/wandb/sdk/interface/interface_shared.py", line 38, in _publish_output_raw
    self._publish(rec)
  File "/home/qrbao/anaconda3/envs/rllib/lib/python3.10/site-packages/wandb/sdk/interface/interface_sock.py", line 39, in _publish
    self._sock_client.send_record_publish(record)
  File "/home/qrbao/anaconda3/envs/rllib/lib/python3.10/site-packages/wandb/sdk/lib/sock_client.py", line 174, in send_record_publish
    self.send_server_request(server_req)
  File "/home/qrbao/anaconda3/envs/rllib/lib/python3.10/site-packages/wandb/sdk/lib/sock_client.py", line 154, in send_server_request
    self._send_message(msg)
  File "/home/qrbao/anaconda3/envs/rllib/lib/python3.10/site-packages/wandb/sdk/lib/sock_client.py", line 151, in _send_message
    self._sendall_with_error_handle(header + data)
  File "/home/qrbao/anaconda3/envs/rllib/lib/python3.10/site-packages/wandb/sdk/lib/sock_client.py", line 130, in _sendall_with_error_handle
    sent = self._sock.send(data)
BrokenPipeError: [Errno 32] Broken pipe
2025-07-09 14:55:41,010 ERROR   MainThread:164079 [redirect.py:_on_write():664] [no run ID] error in stderr callback
Traceback (most recent call last):
  File "/home/qrbao/anaconda3/envs/rllib/lib/python3.10/site-packages/wandb/sdk/lib/redirect.py", line 662, in _on_write
    cb(written_data)
  File "/home/qrbao/anaconda3/envs/rllib/lib/python3.10/site-packages/wandb/sdk/wandb_run.py", line 2380, in <lambda>
    lambda data: self._console_raw_callback("stderr", data),
  File "/home/qrbao/anaconda3/envs/rllib/lib/python3.10/site-packages/wandb/sdk/wandb_run.py", line 391, in wrapper
    return func(self, *args, **kwargs)
  File "/home/qrbao/anaconda3/envs/rllib/lib/python3.10/site-packages/wandb/sdk/wandb_run.py", line 449, in wrapper_fn
    return func(self, *args, **kwargs)
  File "/home/qrbao/anaconda3/envs/rllib/lib/python3.10/site-packages/wandb/sdk/wandb_run.py", line 1561, in _console_raw_callback
    self._backend.interface.publish_output_raw(name, data)
  File "/home/qrbao/anaconda3/envs/rllib/lib/python3.10/site-packages/wandb/sdk/interface/interface.py", line 772, in publish_output_raw
    self._publish_output_raw(o)
  File "/home/qrbao/anaconda3/envs/rllib/lib/python3.10/site-packages/wandb/sdk/interface/interface_shared.py", line 38, in _publish_output_raw
    self._publish(rec)
  File "/home/qrbao/anaconda3/envs/rllib/lib/python3.10/site-packages/wandb/sdk/interface/interface_sock.py", line 39, in _publish
    self._sock_client.send_record_publish(record)
  File "/home/qrbao/anaconda3/envs/rllib/lib/python3.10/site-packages/wandb/sdk/lib/sock_client.py", line 174, in send_record_publish
    self.send_server_request(server_req)
  File "/home/qrbao/anaconda3/envs/rllib/lib/python3.10/site-packages/wandb/sdk/lib/sock_client.py", line 154, in send_server_request
    self._send_message(msg)
  File "/home/qrbao/anaconda3/envs/rllib/lib/python3.10/site-packages/wandb/sdk/lib/sock_client.py", line 151, in _send_message
    self._sendall_with_error_handle(header + data)
  File "/home/qrbao/anaconda3/envs/rllib/lib/python3.10/site-packages/wandb/sdk/lib/sock_client.py", line 130, in _sendall_with_error_handle
    sent = self._sock.send(data)
BrokenPipeError: [Errno 32] Broken pipe
2025-07-09 14:55:41,010 ERROR   MainThread:164079 [redirect.py:_on_write():664] [no run ID] error in stderr callback
Traceback (most recent call last):
  File "/home/qrbao/anaconda3/envs/rllib/lib/python3.10/site-packages/wandb/sdk/lib/redirect.py", line 662, in _on_write
    cb(written_data)
  File "/home/qrbao/anaconda3/envs/rllib/lib/python3.10/site-packages/wandb/sdk/wandb_run.py", line 2380, in <lambda>
    lambda data: self._console_raw_callback("stderr", data),
  File "/home/qrbao/anaconda3/envs/rllib/lib/python3.10/site-packages/wandb/sdk/wandb_run.py", line 391, in wrapper
    return func(self, *args, **kwargs)
  File "/home/qrbao/anaconda3/envs/rllib/lib/python3.10/site-packages/wandb/sdk/wandb_run.py", line 449, in wrapper_fn
    return func(self, *args, **kwargs)
  File "/home/qrbao/anaconda3/envs/rllib/lib/python3.10/site-packages/wandb/sdk/wandb_run.py", line 1561, in _console_raw_callback
    self._backend.interface.publish_output_raw(name, data)
  File "/home/qrbao/anaconda3/envs/rllib/lib/python3.10/site-packages/wandb/sdk/interface/interface.py", line 772, in publish_output_raw
    self._publish_output_raw(o)
  File "/home/qrbao/anaconda3/envs/rllib/lib/python3.10/site-packages/wandb/sdk/interface/interface_shared.py", line 38, in _publish_output_raw
    self._publish(rec)
  File "/home/qrbao/anaconda3/envs/rllib/lib/python3.10/site-packages/wandb/sdk/interface/interface_sock.py", line 39, in _publish
    self._sock_client.send_record_publish(record)
  File "/home/qrbao/anaconda3/envs/rllib/lib/python3.10/site-packages/wandb/sdk/lib/sock_client.py", line 174, in send_record_publish
    self.send_server_request(server_req)
  File "/home/qrbao/anaconda3/envs/rllib/lib/python3.10/site-packages/wandb/sdk/lib/sock_client.py", line 154, in send_server_request
    self._send_message(msg)
  File "/home/qrbao/anaconda3/envs/rllib/lib/python3.10/site-packages/wandb/sdk/lib/sock_client.py", line 151, in _send_message
    self._sendall_with_error_handle(header + data)
  File "/home/qrbao/anaconda3/envs/rllib/lib/python3.10/site-packages/wandb/sdk/lib/sock_client.py", line 130, in _sendall_with_error_handle
    sent = self._sock.send(data)
BrokenPipeError: [Errno 32] Broken pipe
2025-07-09 14:55:41,010 ERROR   MainThread:164079 [redirect.py:_on_write():664] [no run ID] error in stderr callback
Traceback (most recent call last):
  File "/home/qrbao/anaconda3/envs/rllib/lib/python3.10/site-packages/wandb/sdk/lib/redirect.py", line 662, in _on_write
    cb(written_data)
  File "/home/qrbao/anaconda3/envs/rllib/lib/python3.10/site-packages/wandb/sdk/wandb_run.py", line 2380, in <lambda>
    lambda data: self._console_raw_callback("stderr", data),
  File "/home/qrbao/anaconda3/envs/rllib/lib/python3.10/site-packages/wandb/sdk/wandb_run.py", line 391, in wrapper
    return func(self, *args, **kwargs)
  File "/home/qrbao/anaconda3/envs/rllib/lib/python3.10/site-packages/wandb/sdk/wandb_run.py", line 449, in wrapper_fn
    return func(self, *args, **kwargs)
  File "/home/qrbao/anaconda3/envs/rllib/lib/python3.10/site-packages/wandb/sdk/wandb_run.py", line 1561, in _console_raw_callback
    self._backend.interface.publish_output_raw(name, data)
  File "/home/qrbao/anaconda3/envs/rllib/lib/python3.10/site-packages/wandb/sdk/interface/interface.py", line 772, in publish_output_raw
    self._publish_output_raw(o)
  File "/home/qrbao/anaconda3/envs/rllib/lib/python3.10/site-packages/wandb/sdk/interface/interface_shared.py", line 38, in _publish_output_raw
    self._publish(rec)
  File "/home/qrbao/anaconda3/envs/rllib/lib/python3.10/site-packages/wandb/sdk/interface/interface_sock.py", line 39, in _publish
    self._sock_client.send_record_publish(record)
  File "/home/qrbao/anaconda3/envs/rllib/lib/python3.10/site-packages/wandb/sdk/lib/sock_client.py", line 174, in send_record_publish
    self.send_server_request(server_req)
  File "/home/qrbao/anaconda3/envs/rllib/lib/python3.10/site-packages/wandb/sdk/lib/sock_client.py", line 154, in send_server_request
    self._send_message(msg)
  File "/home/qrbao/anaconda3/envs/rllib/lib/python3.10/site-packages/wandb/sdk/lib/sock_client.py", line 151, in _send_message
    self._sendall_with_error_handle(header + data)
  File "/home/qrbao/anaconda3/envs/rllib/lib/python3.10/site-packages/wandb/sdk/lib/sock_client.py", line 130, in _sendall_with_error_handle
    sent = self._sock.send(data)
BrokenPipeError: [Errno 32] Broken pipe
2025-07-09 14:55:41,011 ERROR   MainThread:164079 [redirect.py:_on_write():664] [no run ID] error in stderr callback
Traceback (most recent call last):
  File "/home/qrbao/anaconda3/envs/rllib/lib/python3.10/site-packages/wandb/sdk/lib/redirect.py", line 662, in _on_write
    cb(written_data)
  File "/home/qrbao/anaconda3/envs/rllib/lib/python3.10/site-packages/wandb/sdk/wandb_run.py", line 2380, in <lambda>
    lambda data: self._console_raw_callback("stderr", data),
  File "/home/qrbao/anaconda3/envs/rllib/lib/python3.10/site-packages/wandb/sdk/wandb_run.py", line 391, in wrapper
    return func(self, *args, **kwargs)
  File "/home/qrbao/anaconda3/envs/rllib/lib/python3.10/site-packages/wandb/sdk/wandb_run.py", line 449, in wrapper_fn
    return func(self, *args, **kwargs)
  File "/home/qrbao/anaconda3/envs/rllib/lib/python3.10/site-packages/wandb/sdk/wandb_run.py", line 1561, in _console_raw_callback
    self._backend.interface.publish_output_raw(name, data)
  File "/home/qrbao/anaconda3/envs/rllib/lib/python3.10/site-packages/wandb/sdk/interface/interface.py", line 772, in publish_output_raw
    self._publish_output_raw(o)
  File "/home/qrbao/anaconda3/envs/rllib/lib/python3.10/site-packages/wandb/sdk/interface/interface_shared.py", line 38, in _publish_output_raw
    self._publish(rec)
  File "/home/qrbao/anaconda3/envs/rllib/lib/python3.10/site-packages/wandb/sdk/interface/interface_sock.py", line 39, in _publish
    self._sock_client.send_record_publish(record)
  File "/home/qrbao/anaconda3/envs/rllib/lib/python3.10/site-packages/wandb/sdk/lib/sock_client.py", line 174, in send_record_publish
    self.send_server_request(server_req)
  File "/home/qrbao/anaconda3/envs/rllib/lib/python3.10/site-packages/wandb/sdk/lib/sock_client.py", line 154, in send_server_request
    self._send_message(msg)
  File "/home/qrbao/anaconda3/envs/rllib/lib/python3.10/site-packages/wandb/sdk/lib/sock_client.py", line 151, in _send_message
    self._sendall_with_error_handle(header + data)
  File "/home/qrbao/anaconda3/envs/rllib/lib/python3.10/site-packages/wandb/sdk/lib/sock_client.py", line 130, in _sendall_with_error_handle
    sent = self._sock.send(data)
BrokenPipeError: [Errno 32] Broken pipe
2025-07-09 14:55:41,011 ERROR   MainThread:164079 [redirect.py:_on_write():664] [no run ID] error in stderr callback
Traceback (most recent call last):
  File "/home/qrbao/anaconda3/envs/rllib/lib/python3.10/site-packages/wandb/sdk/lib/redirect.py", line 662, in _on_write
    cb(written_data)
  File "/home/qrbao/anaconda3/envs/rllib/lib/python3.10/site-packages/wandb/sdk/wandb_run.py", line 2380, in <lambda>
    lambda data: self._console_raw_callback("stderr", data),
  File "/home/qrbao/anaconda3/envs/rllib/lib/python3.10/site-packages/wandb/sdk/wandb_run.py", line 391, in wrapper
    return func(self, *args, **kwargs)
  File "/home/qrbao/anaconda3/envs/rllib/lib/python3.10/site-packages/wandb/sdk/wandb_run.py", line 449, in wrapper_fn
    return func(self, *args, **kwargs)
  File "/home/qrbao/anaconda3/envs/rllib/lib/python3.10/site-packages/wandb/sdk/wandb_run.py", line 1561, in _console_raw_callback
    self._backend.interface.publish_output_raw(name, data)
  File "/home/qrbao/anaconda3/envs/rllib/lib/python3.10/site-packages/wandb/sdk/interface/interface.py", line 772, in publish_output_raw
    self._publish_output_raw(o)
  File "/home/qrbao/anaconda3/envs/rllib/lib/python3.10/site-packages/wandb/sdk/interface/interface_shared.py", line 38, in _publish_output_raw
    self._publish(rec)
  File "/home/qrbao/anaconda3/envs/rllib/lib/python3.10/site-packages/wandb/sdk/interface/interface_sock.py", line 39, in _publish
    self._sock_client.send_record_publish(record)
  File "/home/qrbao/anaconda3/envs/rllib/lib/python3.10/site-packages/wandb/sdk/lib/sock_client.py", line 174, in send_record_publish
    self.send_server_request(server_req)
  File "/home/qrbao/anaconda3/envs/rllib/lib/python3.10/site-packages/wandb/sdk/lib/sock_client.py", line 154, in send_server_request
    self._send_message(msg)
  File "/home/qrbao/anaconda3/envs/rllib/lib/python3.10/site-packages/wandb/sdk/lib/sock_client.py", line 151, in _send_message
    self._sendall_with_error_handle(header + data)
  File "/home/qrbao/anaconda3/envs/rllib/lib/python3.10/site-packages/wandb/sdk/lib/sock_client.py", line 130, in _sendall_with_error_handle
    sent = self._sock.send(data)
BrokenPipeError: [Errno 32] Broken pipe
2025-07-09 14:55:41,011 ERROR   MainThread:164079 [redirect.py:_on_write():664] [no run ID] error in stderr callback
Traceback (most recent call last):
  File "/home/qrbao/anaconda3/envs/rllib/lib/python3.10/site-packages/wandb/sdk/lib/redirect.py", line 662, in _on_write
    cb(written_data)
  File "/home/qrbao/anaconda3/envs/rllib/lib/python3.10/site-packages/wandb/sdk/wandb_run.py", line 2380, in <lambda>
    lambda data: self._console_raw_callback("stderr", data),
  File "/home/qrbao/anaconda3/envs/rllib/lib/python3.10/site-packages/wandb/sdk/wandb_run.py", line 391, in wrapper
    return func(self, *args, **kwargs)
  File "/home/qrbao/anaconda3/envs/rllib/lib/python3.10/site-packages/wandb/sdk/wandb_run.py", line 449, in wrapper_fn
    return func(self, *args, **kwargs)
  File "/home/qrbao/anaconda3/envs/rllib/lib/python3.10/site-packages/wandb/sdk/wandb_run.py", line 1561, in _console_raw_callback
    self._backend.interface.publish_output_raw(name, data)
  File "/home/qrbao/anaconda3/envs/rllib/lib/python3.10/site-packages/wandb/sdk/interface/interface.py", line 772, in publish_output_raw
    self._publish_output_raw(o)
  File "/home/qrbao/anaconda3/envs/rllib/lib/python3.10/site-packages/wandb/sdk/interface/interface_shared.py", line 38, in _publish_output_raw
    self._publish(rec)
  File "/home/qrbao/anaconda3/envs/rllib/lib/python3.10/site-packages/wandb/sdk/interface/interface_sock.py", line 39, in _publish
    self._sock_client.send_record_publish(record)
  File "/home/qrbao/anaconda3/envs/rllib/lib/python3.10/site-packages/wandb/sdk/lib/sock_client.py", line 174, in send_record_publish
    self.send_server_request(server_req)
  File "/home/qrbao/anaconda3/envs/rllib/lib/python3.10/site-packages/wandb/sdk/lib/sock_client.py", line 154, in send_server_request
    self._send_message(msg)
  File "/home/qrbao/anaconda3/envs/rllib/lib/python3.10/site-packages/wandb/sdk/lib/sock_client.py", line 151, in _send_message
    self._sendall_with_error_handle(header + data)
  File "/home/qrbao/anaconda3/envs/rllib/lib/python3.10/site-packages/wandb/sdk/lib/sock_client.py", line 130, in _sendall_with_error_handle
    sent = self._sock.send(data)
BrokenPipeError: [Errno 32] Broken pipe
2025-07-09 14:55:41,011 ERROR   MainThread:164079 [redirect.py:_on_write():664] [no run ID] error in stderr callback
Traceback (most recent call last):
  File "/home/qrbao/anaconda3/envs/rllib/lib/python3.10/site-packages/wandb/sdk/lib/redirect.py", line 662, in _on_write
    cb(written_data)
  File "/home/qrbao/anaconda3/envs/rllib/lib/python3.10/site-packages/wandb/sdk/wandb_run.py", line 2380, in <lambda>
    lambda data: self._console_raw_callback("stderr", data),
  File "/home/qrbao/anaconda3/envs/rllib/lib/python3.10/site-packages/wandb/sdk/wandb_run.py", line 391, in wrapper
    return func(self, *args, **kwargs)
  File "/home/qrbao/anaconda3/envs/rllib/lib/python3.10/site-packages/wandb/sdk/wandb_run.py", line 449, in wrapper_fn
    return func(self, *args, **kwargs)
  File "/home/qrbao/anaconda3/envs/rllib/lib/python3.10/site-packages/wandb/sdk/wandb_run.py", line 1561, in _console_raw_callback
    self._backend.interface.publish_output_raw(name, data)
  File "/home/qrbao/anaconda3/envs/rllib/lib/python3.10/site-packages/wandb/sdk/interface/interface.py", line 772, in publish_output_raw
    self._publish_output_raw(o)
  File "/home/qrbao/anaconda3/envs/rllib/lib/python3.10/site-packages/wandb/sdk/interface/interface_shared.py", line 38, in _publish_output_raw
    self._publish(rec)
  File "/home/qrbao/anaconda3/envs/rllib/lib/python3.10/site-packages/wandb/sdk/interface/interface_sock.py", line 39, in _publish
    self._sock_client.send_record_publish(record)
  File "/home/qrbao/anaconda3/envs/rllib/lib/python3.10/site-packages/wandb/sdk/lib/sock_client.py", line 174, in send_record_publish
    self.send_server_request(server_req)
  File "/home/qrbao/anaconda3/envs/rllib/lib/python3.10/site-packages/wandb/sdk/lib/sock_client.py", line 154, in send_server_request
    self._send_message(msg)
  File "/home/qrbao/anaconda3/envs/rllib/lib/python3.10/site-packages/wandb/sdk/lib/sock_client.py", line 151, in _send_message
    self._sendall_with_error_handle(header + data)
  File "/home/qrbao/anaconda3/envs/rllib/lib/python3.10/site-packages/wandb/sdk/lib/sock_client.py", line 130, in _sendall_with_error_handle
    sent = self._sock.send(data)
BrokenPipeError: [Errno 32] Broken pipe
2025-07-09 14:55:41,011 ERROR   MainThread:164079 [redirect.py:_on_write():664] [no run ID] error in stderr callback
Traceback (most recent call last):
  File "/home/qrbao/anaconda3/envs/rllib/lib/python3.10/site-packages/wandb/sdk/lib/redirect.py", line 662, in _on_write
    cb(written_data)
  File "/home/qrbao/anaconda3/envs/rllib/lib/python3.10/site-packages/wandb/sdk/wandb_run.py", line 2380, in <lambda>
    lambda data: self._console_raw_callback("stderr", data),
  File "/home/qrbao/anaconda3/envs/rllib/lib/python3.10/site-packages/wandb/sdk/wandb_run.py", line 391, in wrapper
    return func(self, *args, **kwargs)
  File "/home/qrbao/anaconda3/envs/rllib/lib/python3.10/site-packages/wandb/sdk/wandb_run.py", line 449, in wrapper_fn
    return func(self, *args, **kwargs)
  File "/home/qrbao/anaconda3/envs/rllib/lib/python3.10/site-packages/wandb/sdk/wandb_run.py", line 1561, in _console_raw_callback
    self._backend.interface.publish_output_raw(name, data)
  File "/home/qrbao/anaconda3/envs/rllib/lib/python3.10/site-packages/wandb/sdk/interface/interface.py", line 772, in publish_output_raw
    self._publish_output_raw(o)
  File "/home/qrbao/anaconda3/envs/rllib/lib/python3.10/site-packages/wandb/sdk/interface/interface_shared.py", line 38, in _publish_output_raw
    self._publish(rec)
  File "/home/qrbao/anaconda3/envs/rllib/lib/python3.10/site-packages/wandb/sdk/interface/interface_sock.py", line 39, in _publish
    self._sock_client.send_record_publish(record)
  File "/home/qrbao/anaconda3/envs/rllib/lib/python3.10/site-packages/wandb/sdk/lib/sock_client.py", line 174, in send_record_publish
    self.send_server_request(server_req)
  File "/home/qrbao/anaconda3/envs/rllib/lib/python3.10/site-packages/wandb/sdk/lib/sock_client.py", line 154, in send_server_request
    self._send_message(msg)
  File "/home/qrbao/anaconda3/envs/rllib/lib/python3.10/site-packages/wandb/sdk/lib/sock_client.py", line 151, in _send_message
    self._sendall_with_error_handle(header + data)
  File "/home/qrbao/anaconda3/envs/rllib/lib/python3.10/site-packages/wandb/sdk/lib/sock_client.py", line 130, in _sendall_with_error_handle
    sent = self._sock.send(data)
BrokenPipeError: [Errno 32] Broken pipe
2025-07-09 14:55:41,011 ERROR   MainThread:164079 [redirect.py:_on_write():664] [no run ID] error in stderr callback
Traceback (most recent call last):
  File "/home/qrbao/anaconda3/envs/rllib/lib/python3.10/site-packages/wandb/sdk/lib/redirect.py", line 662, in _on_write
    cb(written_data)
  File "/home/qrbao/anaconda3/envs/rllib/lib/python3.10/site-packages/wandb/sdk/wandb_run.py", line 2380, in <lambda>
    lambda data: self._console_raw_callback("stderr", data),
  File "/home/qrbao/anaconda3/envs/rllib/lib/python3.10/site-packages/wandb/sdk/wandb_run.py", line 391, in wrapper
    return func(self, *args, **kwargs)
  File "/home/qrbao/anaconda3/envs/rllib/lib/python3.10/site-packages/wandb/sdk/wandb_run.py", line 449, in wrapper_fn
    return func(self, *args, **kwargs)
  File "/home/qrbao/anaconda3/envs/rllib/lib/python3.10/site-packages/wandb/sdk/wandb_run.py", line 1561, in _console_raw_callback
    self._backend.interface.publish_output_raw(name, data)
  File "/home/qrbao/anaconda3/envs/rllib/lib/python3.10/site-packages/wandb/sdk/interface/interface.py", line 772, in publish_output_raw
    self._publish_output_raw(o)
  File "/home/qrbao/anaconda3/envs/rllib/lib/python3.10/site-packages/wandb/sdk/interface/interface_shared.py", line 38, in _publish_output_raw
    self._publish(rec)
  File "/home/qrbao/anaconda3/envs/rllib/lib/python3.10/site-packages/wandb/sdk/interface/interface_sock.py", line 39, in _publish
    self._sock_client.send_record_publish(record)
  File "/home/qrbao/anaconda3/envs/rllib/lib/python3.10/site-packages/wandb/sdk/lib/sock_client.py", line 174, in send_record_publish
    self.send_server_request(server_req)
  File "/home/qrbao/anaconda3/envs/rllib/lib/python3.10/site-packages/wandb/sdk/lib/sock_client.py", line 154, in send_server_request
    self._send_message(msg)
  File "/home/qrbao/anaconda3/envs/rllib/lib/python3.10/site-packages/wandb/sdk/lib/sock_client.py", line 151, in _send_message
    self._sendall_with_error_handle(header + data)
  File "/home/qrbao/anaconda3/envs/rllib/lib/python3.10/site-packages/wandb/sdk/lib/sock_client.py", line 130, in _sendall_with_error_handle
    sent = self._sock.send(data)
BrokenPipeError: [Errno 32] Broken pipe
2025-07-09 14:55:41,011 ERROR   MainThread:164079 [redirect.py:_on_write():664] [no run ID] error in stderr callback
Traceback (most recent call last):
  File "/home/qrbao/anaconda3/envs/rllib/lib/python3.10/site-packages/wandb/sdk/lib/redirect.py", line 662, in _on_write
    cb(written_data)
  File "/home/qrbao/anaconda3/envs/rllib/lib/python3.10/site-packages/wandb/sdk/wandb_run.py", line 2380, in <lambda>
    lambda data: self._console_raw_callback("stderr", data),
  File "/home/qrbao/anaconda3/envs/rllib/lib/python3.10/site-packages/wandb/sdk/wandb_run.py", line 391, in wrapper
    return func(self, *args, **kwargs)
  File "/home/qrbao/anaconda3/envs/rllib/lib/python3.10/site-packages/wandb/sdk/wandb_run.py", line 449, in wrapper_fn
    return func(self, *args, **kwargs)
  File "/home/qrbao/anaconda3/envs/rllib/lib/python3.10/site-packages/wandb/sdk/wandb_run.py", line 1561, in _console_raw_callback
    self._backend.interface.publish_output_raw(name, data)
  File "/home/qrbao/anaconda3/envs/rllib/lib/python3.10/site-packages/wandb/sdk/interface/interface.py", line 772, in publish_output_raw
    self._publish_output_raw(o)
  File "/home/qrbao/anaconda3/envs/rllib/lib/python3.10/site-packages/wandb/sdk/interface/interface_shared.py", line 38, in _publish_output_raw
    self._publish(rec)
  File "/home/qrbao/anaconda3/envs/rllib/lib/python3.10/site-packages/wandb/sdk/interface/interface_sock.py", line 39, in _publish
    self._sock_client.send_record_publish(record)
  File "/home/qrbao/anaconda3/envs/rllib/lib/python3.10/site-packages/wandb/sdk/lib/sock_client.py", line 174, in send_record_publish
    self.send_server_request(server_req)
  File "/home/qrbao/anaconda3/envs/rllib/lib/python3.10/site-packages/wandb/sdk/lib/sock_client.py", line 154, in send_server_request
    self._send_message(msg)
  File "/home/qrbao/anaconda3/envs/rllib/lib/python3.10/site-packages/wandb/sdk/lib/sock_client.py", line 151, in _send_message
    self._sendall_with_error_handle(header + data)
  File "/home/qrbao/anaconda3/envs/rllib/lib/python3.10/site-packages/wandb/sdk/lib/sock_client.py", line 130, in _sendall_with_error_handle
    sent = self._sock.send(data)
BrokenPipeError: [Errno 32] Broken pipe
2025-07-09 14:55:41,011 ERROR   MainThread:164079 [redirect.py:_on_write():664] [no run ID] error in stderr callback
Traceback (most recent call last):
  File "/home/qrbao/anaconda3/envs/rllib/lib/python3.10/site-packages/wandb/sdk/lib/redirect.py", line 662, in _on_write
    cb(written_data)
  File "/home/qrbao/anaconda3/envs/rllib/lib/python3.10/site-packages/wandb/sdk/wandb_run.py", line 2380, in <lambda>
    lambda data: self._console_raw_callback("stderr", data),
  File "/home/qrbao/anaconda3/envs/rllib/lib/python3.10/site-packages/wandb/sdk/wandb_run.py", line 391, in wrapper
    return func(self, *args, **kwargs)
  File "/home/qrbao/anaconda3/envs/rllib/lib/python3.10/site-packages/wandb/sdk/wandb_run.py", line 449, in wrapper_fn
    return func(self, *args, **kwargs)
  File "/home/qrbao/anaconda3/envs/rllib/lib/python3.10/site-packages/wandb/sdk/wandb_run.py", line 1561, in _console_raw_callback
    self._backend.interface.publish_output_raw(name, data)
  File "/home/qrbao/anaconda3/envs/rllib/lib/python3.10/site-packages/wandb/sdk/interface/interface.py", line 772, in publish_output_raw
    self._publish_output_raw(o)
  File "/home/qrbao/anaconda3/envs/rllib/lib/python3.10/site-packages/wandb/sdk/interface/interface_shared.py", line 38, in _publish_output_raw
    self._publish(rec)
  File "/home/qrbao/anaconda3/envs/rllib/lib/python3.10/site-packages/wandb/sdk/interface/interface_sock.py", line 39, in _publish
    self._sock_client.send_record_publish(record)
  File "/home/qrbao/anaconda3/envs/rllib/lib/python3.10/site-packages/wandb/sdk/lib/sock_client.py", line 174, in send_record_publish
    self.send_server_request(server_req)
  File "/home/qrbao/anaconda3/envs/rllib/lib/python3.10/site-packages/wandb/sdk/lib/sock_client.py", line 154, in send_server_request
    self._send_message(msg)
  File "/home/qrbao/anaconda3/envs/rllib/lib/python3.10/site-packages/wandb/sdk/lib/sock_client.py", line 151, in _send_message
    self._sendall_with_error_handle(header + data)
  File "/home/qrbao/anaconda3/envs/rllib/lib/python3.10/site-packages/wandb/sdk/lib/sock_client.py", line 130, in _sendall_with_error_handle
    sent = self._sock.send(data)
BrokenPipeError: [Errno 32] Broken pipe
2025-07-09 14:55:41,012 ERROR   MainThread:164079 [redirect.py:_on_write():664] [no run ID] error in stderr callback
Traceback (most recent call last):
  File "/home/qrbao/anaconda3/envs/rllib/lib/python3.10/site-packages/wandb/sdk/lib/redirect.py", line 662, in _on_write
    cb(written_data)
  File "/home/qrbao/anaconda3/envs/rllib/lib/python3.10/site-packages/wandb/sdk/wandb_run.py", line 2380, in <lambda>
    lambda data: self._console_raw_callback("stderr", data),
  File "/home/qrbao/anaconda3/envs/rllib/lib/python3.10/site-packages/wandb/sdk/wandb_run.py", line 391, in wrapper
    return func(self, *args, **kwargs)
  File "/home/qrbao/anaconda3/envs/rllib/lib/python3.10/site-packages/wandb/sdk/wandb_run.py", line 449, in wrapper_fn
    return func(self, *args, **kwargs)
  File "/home/qrbao/anaconda3/envs/rllib/lib/python3.10/site-packages/wandb/sdk/wandb_run.py", line 1561, in _console_raw_callback
    self._backend.interface.publish_output_raw(name, data)
  File "/home/qrbao/anaconda3/envs/rllib/lib/python3.10/site-packages/wandb/sdk/interface/interface.py", line 772, in publish_output_raw
    self._publish_output_raw(o)
  File "/home/qrbao/anaconda3/envs/rllib/lib/python3.10/site-packages/wandb/sdk/interface/interface_shared.py", line 38, in _publish_output_raw
    self._publish(rec)
  File "/home/qrbao/anaconda3/envs/rllib/lib/python3.10/site-packages/wandb/sdk/interface/interface_sock.py", line 39, in _publish
    self._sock_client.send_record_publish(record)
  File "/home/qrbao/anaconda3/envs/rllib/lib/python3.10/site-packages/wandb/sdk/lib/sock_client.py", line 174, in send_record_publish
    self.send_server_request(server_req)
  File "/home/qrbao/anaconda3/envs/rllib/lib/python3.10/site-packages/wandb/sdk/lib/sock_client.py", line 154, in send_server_request
    self._send_message(msg)
  File "/home/qrbao/anaconda3/envs/rllib/lib/python3.10/site-packages/wandb/sdk/lib/sock_client.py", line 151, in _send_message
    self._sendall_with_error_handle(header + data)
  File "/home/qrbao/anaconda3/envs/rllib/lib/python3.10/site-packages/wandb/sdk/lib/sock_client.py", line 130, in _sendall_with_error_handle
    sent = self._sock.send(data)
BrokenPipeError: [Errno 32] Broken pipe
2025-07-09 14:55:41,012 ERROR   MainThread:164079 [redirect.py:_on_write():664] [no run ID] error in stderr callback
Traceback (most recent call last):
  File "/home/qrbao/anaconda3/envs/rllib/lib/python3.10/site-packages/wandb/sdk/lib/redirect.py", line 662, in _on_write
    cb(written_data)
  File "/home/qrbao/anaconda3/envs/rllib/lib/python3.10/site-packages/wandb/sdk/wandb_run.py", line 2380, in <lambda>
    lambda data: self._console_raw_callback("stderr", data),
  File "/home/qrbao/anaconda3/envs/rllib/lib/python3.10/site-packages/wandb/sdk/wandb_run.py", line 391, in wrapper
    return func(self, *args, **kwargs)
  File "/home/qrbao/anaconda3/envs/rllib/lib/python3.10/site-packages/wandb/sdk/wandb_run.py", line 449, in wrapper_fn
    return func(self, *args, **kwargs)
  File "/home/qrbao/anaconda3/envs/rllib/lib/python3.10/site-packages/wandb/sdk/wandb_run.py", line 1561, in _console_raw_callback
    self._backend.interface.publish_output_raw(name, data)
  File "/home/qrbao/anaconda3/envs/rllib/lib/python3.10/site-packages/wandb/sdk/interface/interface.py", line 772, in publish_output_raw
    self._publish_output_raw(o)
  File "/home/qrbao/anaconda3/envs/rllib/lib/python3.10/site-packages/wandb/sdk/interface/interface_shared.py", line 38, in _publish_output_raw
    self._publish(rec)
  File "/home/qrbao/anaconda3/envs/rllib/lib/python3.10/site-packages/wandb/sdk/interface/interface_sock.py", line 39, in _publish
    self._sock_client.send_record_publish(record)
  File "/home/qrbao/anaconda3/envs/rllib/lib/python3.10/site-packages/wandb/sdk/lib/sock_client.py", line 174, in send_record_publish
    self.send_server_request(server_req)
  File "/home/qrbao/anaconda3/envs/rllib/lib/python3.10/site-packages/wandb/sdk/lib/sock_client.py", line 154, in send_server_request
    self._send_message(msg)
  File "/home/qrbao/anaconda3/envs/rllib/lib/python3.10/site-packages/wandb/sdk/lib/sock_client.py", line 151, in _send_message
    self._sendall_with_error_handle(header + data)
  File "/home/qrbao/anaconda3/envs/rllib/lib/python3.10/site-packages/wandb/sdk/lib/sock_client.py", line 130, in _sendall_with_error_handle
    sent = self._sock.send(data)
BrokenPipeError: [Errno 32] Broken pipe
2025-07-09 14:55:41,012 ERROR   MainThread:164079 [redirect.py:_on_write():664] [no run ID] error in stderr callback
Traceback (most recent call last):
  File "/home/qrbao/anaconda3/envs/rllib/lib/python3.10/site-packages/wandb/sdk/lib/redirect.py", line 662, in _on_write
    cb(written_data)
  File "/home/qrbao/anaconda3/envs/rllib/lib/python3.10/site-packages/wandb/sdk/wandb_run.py", line 2380, in <lambda>
    lambda data: self._console_raw_callback("stderr", data),
  File "/home/qrbao/anaconda3/envs/rllib/lib/python3.10/site-packages/wandb/sdk/wandb_run.py", line 391, in wrapper
    return func(self, *args, **kwargs)
  File "/home/qrbao/anaconda3/envs/rllib/lib/python3.10/site-packages/wandb/sdk/wandb_run.py", line 449, in wrapper_fn
    return func(self, *args, **kwargs)
  File "/home/qrbao/anaconda3/envs/rllib/lib/python3.10/site-packages/wandb/sdk/wandb_run.py", line 1561, in _console_raw_callback
    self._backend.interface.publish_output_raw(name, data)
  File "/home/qrbao/anaconda3/envs/rllib/lib/python3.10/site-packages/wandb/sdk/interface/interface.py", line 772, in publish_output_raw
    self._publish_output_raw(o)
  File "/home/qrbao/anaconda3/envs/rllib/lib/python3.10/site-packages/wandb/sdk/interface/interface_shared.py", line 38, in _publish_output_raw
    self._publish(rec)
  File "/home/qrbao/anaconda3/envs/rllib/lib/python3.10/site-packages/wandb/sdk/interface/interface_sock.py", line 39, in _publish
    self._sock_client.send_record_publish(record)
  File "/home/qrbao/anaconda3/envs/rllib/lib/python3.10/site-packages/wandb/sdk/lib/sock_client.py", line 174, in send_record_publish
    self.send_server_request(server_req)
  File "/home/qrbao/anaconda3/envs/rllib/lib/python3.10/site-packages/wandb/sdk/lib/sock_client.py", line 154, in send_server_request
    self._send_message(msg)
  File "/home/qrbao/anaconda3/envs/rllib/lib/python3.10/site-packages/wandb/sdk/lib/sock_client.py", line 151, in _send_message
    self._sendall_with_error_handle(header + data)
  File "/home/qrbao/anaconda3/envs/rllib/lib/python3.10/site-packages/wandb/sdk/lib/sock_client.py", line 130, in _sendall_with_error_handle
    sent = self._sock.send(data)
BrokenPipeError: [Errno 32] Broken pipe
2025-07-09 14:55:41,012 ERROR   MainThread:164079 [redirect.py:_on_write():664] [no run ID] error in stderr callback
Traceback (most recent call last):
  File "/home/qrbao/anaconda3/envs/rllib/lib/python3.10/site-packages/wandb/sdk/lib/redirect.py", line 662, in _on_write
    cb(written_data)
  File "/home/qrbao/anaconda3/envs/rllib/lib/python3.10/site-packages/wandb/sdk/wandb_run.py", line 2380, in <lambda>
    lambda data: self._console_raw_callback("stderr", data),
  File "/home/qrbao/anaconda3/envs/rllib/lib/python3.10/site-packages/wandb/sdk/wandb_run.py", line 391, in wrapper
    return func(self, *args, **kwargs)
  File "/home/qrbao/anaconda3/envs/rllib/lib/python3.10/site-packages/wandb/sdk/wandb_run.py", line 449, in wrapper_fn
    return func(self, *args, **kwargs)
  File "/home/qrbao/anaconda3/envs/rllib/lib/python3.10/site-packages/wandb/sdk/wandb_run.py", line 1561, in _console_raw_callback
    self._backend.interface.publish_output_raw(name, data)
  File "/home/qrbao/anaconda3/envs/rllib/lib/python3.10/site-packages/wandb/sdk/interface/interface.py", line 772, in publish_output_raw
    self._publish_output_raw(o)
  File "/home/qrbao/anaconda3/envs/rllib/lib/python3.10/site-packages/wandb/sdk/interface/interface_shared.py", line 38, in _publish_output_raw
    self._publish(rec)
  File "/home/qrbao/anaconda3/envs/rllib/lib/python3.10/site-packages/wandb/sdk/interface/interface_sock.py", line 39, in _publish
    self._sock_client.send_record_publish(record)
  File "/home/qrbao/anaconda3/envs/rllib/lib/python3.10/site-packages/wandb/sdk/lib/sock_client.py", line 174, in send_record_publish
    self.send_server_request(server_req)
  File "/home/qrbao/anaconda3/envs/rllib/lib/python3.10/site-packages/wandb/sdk/lib/sock_client.py", line 154, in send_server_request
    self._send_message(msg)
  File "/home/qrbao/anaconda3/envs/rllib/lib/python3.10/site-packages/wandb/sdk/lib/sock_client.py", line 151, in _send_message
    self._sendall_with_error_handle(header + data)
  File "/home/qrbao/anaconda3/envs/rllib/lib/python3.10/site-packages/wandb/sdk/lib/sock_client.py", line 130, in _sendall_with_error_handle
    sent = self._sock.send(data)
BrokenPipeError: [Errno 32] Broken pipe
2025-07-09 14:55:41,012 ERROR   MainThread:164079 [redirect.py:_on_write():664] [no run ID] error in stderr callback
Traceback (most recent call last):
  File "/home/qrbao/anaconda3/envs/rllib/lib/python3.10/site-packages/wandb/sdk/lib/redirect.py", line 662, in _on_write
    cb(written_data)
  File "/home/qrbao/anaconda3/envs/rllib/lib/python3.10/site-packages/wandb/sdk/wandb_run.py", line 2380, in <lambda>
    lambda data: self._console_raw_callback("stderr", data),
  File "/home/qrbao/anaconda3/envs/rllib/lib/python3.10/site-packages/wandb/sdk/wandb_run.py", line 391, in wrapper
    return func(self, *args, **kwargs)
  File "/home/qrbao/anaconda3/envs/rllib/lib/python3.10/site-packages/wandb/sdk/wandb_run.py", line 449, in wrapper_fn
    return func(self, *args, **kwargs)
  File "/home/qrbao/anaconda3/envs/rllib/lib/python3.10/site-packages/wandb/sdk/wandb_run.py", line 1561, in _console_raw_callback
    self._backend.interface.publish_output_raw(name, data)
  File "/home/qrbao/anaconda3/envs/rllib/lib/python3.10/site-packages/wandb/sdk/interface/interface.py", line 772, in publish_output_raw
    self._publish_output_raw(o)
  File "/home/qrbao/anaconda3/envs/rllib/lib/python3.10/site-packages/wandb/sdk/interface/interface_shared.py", line 38, in _publish_output_raw
    self._publish(rec)
  File "/home/qrbao/anaconda3/envs/rllib/lib/python3.10/site-packages/wandb/sdk/interface/interface_sock.py", line 39, in _publish
    self._sock_client.send_record_publish(record)
  File "/home/qrbao/anaconda3/envs/rllib/lib/python3.10/site-packages/wandb/sdk/lib/sock_client.py", line 174, in send_record_publish
    self.send_server_request(server_req)
  File "/home/qrbao/anaconda3/envs/rllib/lib/python3.10/site-packages/wandb/sdk/lib/sock_client.py", line 154, in send_server_request
    self._send_message(msg)
  File "/home/qrbao/anaconda3/envs/rllib/lib/python3.10/site-packages/wandb/sdk/lib/sock_client.py", line 151, in _send_message
    self._sendall_with_error_handle(header + data)
  File "/home/qrbao/anaconda3/envs/rllib/lib/python3.10/site-packages/wandb/sdk/lib/sock_client.py", line 130, in _sendall_with_error_handle
    sent = self._sock.send(data)
BrokenPipeError: [Errno 32] Broken pipe
2025-07-09 14:55:41,012 ERROR   MainThread:164079 [redirect.py:_on_write():664] [no run ID] error in stderr callback
Traceback (most recent call last):
  File "/home/qrbao/anaconda3/envs/rllib/lib/python3.10/site-packages/wandb/sdk/lib/redirect.py", line 662, in _on_write
    cb(written_data)
  File "/home/qrbao/anaconda3/envs/rllib/lib/python3.10/site-packages/wandb/sdk/wandb_run.py", line 2380, in <lambda>
    lambda data: self._console_raw_callback("stderr", data),
  File "/home/qrbao/anaconda3/envs/rllib/lib/python3.10/site-packages/wandb/sdk/wandb_run.py", line 391, in wrapper
    return func(self, *args, **kwargs)
  File "/home/qrbao/anaconda3/envs/rllib/lib/python3.10/site-packages/wandb/sdk/wandb_run.py", line 449, in wrapper_fn
    return func(self, *args, **kwargs)
  File "/home/qrbao/anaconda3/envs/rllib/lib/python3.10/site-packages/wandb/sdk/wandb_run.py", line 1561, in _console_raw_callback
    self._backend.interface.publish_output_raw(name, data)
  File "/home/qrbao/anaconda3/envs/rllib/lib/python3.10/site-packages/wandb/sdk/interface/interface.py", line 772, in publish_output_raw
    self._publish_output_raw(o)
  File "/home/qrbao/anaconda3/envs/rllib/lib/python3.10/site-packages/wandb/sdk/interface/interface_shared.py", line 38, in _publish_output_raw
    self._publish(rec)
  File "/home/qrbao/anaconda3/envs/rllib/lib/python3.10/site-packages/wandb/sdk/interface/interface_sock.py", line 39, in _publish
    self._sock_client.send_record_publish(record)
  File "/home/qrbao/anaconda3/envs/rllib/lib/python3.10/site-packages/wandb/sdk/lib/sock_client.py", line 174, in send_record_publish
    self.send_server_request(server_req)
  File "/home/qrbao/anaconda3/envs/rllib/lib/python3.10/site-packages/wandb/sdk/lib/sock_client.py", line 154, in send_server_request
    self._send_message(msg)
  File "/home/qrbao/anaconda3/envs/rllib/lib/python3.10/site-packages/wandb/sdk/lib/sock_client.py", line 151, in _send_message
    self._sendall_with_error_handle(header + data)
  File "/home/qrbao/anaconda3/envs/rllib/lib/python3.10/site-packages/wandb/sdk/lib/sock_client.py", line 130, in _sendall_with_error_handle
    sent = self._sock.send(data)
BrokenPipeError: [Errno 32] Broken pipe
2025-07-09 14:55:41,012 ERROR   MainThread:164079 [redirect.py:_on_write():664] [no run ID] error in stderr callback
Traceback (most recent call last):
  File "/home/qrbao/anaconda3/envs/rllib/lib/python3.10/site-packages/wandb/sdk/lib/redirect.py", line 662, in _on_write
    cb(written_data)
  File "/home/qrbao/anaconda3/envs/rllib/lib/python3.10/site-packages/wandb/sdk/wandb_run.py", line 2380, in <lambda>
    lambda data: self._console_raw_callback("stderr", data),
  File "/home/qrbao/anaconda3/envs/rllib/lib/python3.10/site-packages/wandb/sdk/wandb_run.py", line 391, in wrapper
    return func(self, *args, **kwargs)
  File "/home/qrbao/anaconda3/envs/rllib/lib/python3.10/site-packages/wandb/sdk/wandb_run.py", line 449, in wrapper_fn
    return func(self, *args, **kwargs)
  File "/home/qrbao/anaconda3/envs/rllib/lib/python3.10/site-packages/wandb/sdk/wandb_run.py", line 1561, in _console_raw_callback
    self._backend.interface.publish_output_raw(name, data)
  File "/home/qrbao/anaconda3/envs/rllib/lib/python3.10/site-packages/wandb/sdk/interface/interface.py", line 772, in publish_output_raw
    self._publish_output_raw(o)
  File "/home/qrbao/anaconda3/envs/rllib/lib/python3.10/site-packages/wandb/sdk/interface/interface_shared.py", line 38, in _publish_output_raw
    self._publish(rec)
  File "/home/qrbao/anaconda3/envs/rllib/lib/python3.10/site-packages/wandb/sdk/interface/interface_sock.py", line 39, in _publish
    self._sock_client.send_record_publish(record)
  File "/home/qrbao/anaconda3/envs/rllib/lib/python3.10/site-packages/wandb/sdk/lib/sock_client.py", line 174, in send_record_publish
    self.send_server_request(server_req)
  File "/home/qrbao/anaconda3/envs/rllib/lib/python3.10/site-packages/wandb/sdk/lib/sock_client.py", line 154, in send_server_request
    self._send_message(msg)
  File "/home/qrbao/anaconda3/envs/rllib/lib/python3.10/site-packages/wandb/sdk/lib/sock_client.py", line 151, in _send_message
    self._sendall_with_error_handle(header + data)
  File "/home/qrbao/anaconda3/envs/rllib/lib/python3.10/site-packages/wandb/sdk/lib/sock_client.py", line 130, in _sendall_with_error_handle
    sent = self._sock.send(data)
BrokenPipeError: [Errno 32] Broken pipe
2025-07-09 14:55:41,012 ERROR   MainThread:164079 [redirect.py:_on_write():664] [no run ID] error in stderr callback
Traceback (most recent call last):
  File "/home/qrbao/anaconda3/envs/rllib/lib/python3.10/site-packages/wandb/sdk/lib/redirect.py", line 662, in _on_write
    cb(written_data)
  File "/home/qrbao/anaconda3/envs/rllib/lib/python3.10/site-packages/wandb/sdk/wandb_run.py", line 2380, in <lambda>
    lambda data: self._console_raw_callback("stderr", data),
  File "/home/qrbao/anaconda3/envs/rllib/lib/python3.10/site-packages/wandb/sdk/wandb_run.py", line 391, in wrapper
    return func(self, *args, **kwargs)
  File "/home/qrbao/anaconda3/envs/rllib/lib/python3.10/site-packages/wandb/sdk/wandb_run.py", line 449, in wrapper_fn
    return func(self, *args, **kwargs)
  File "/home/qrbao/anaconda3/envs/rllib/lib/python3.10/site-packages/wandb/sdk/wandb_run.py", line 1561, in _console_raw_callback
    self._backend.interface.publish_output_raw(name, data)
  File "/home/qrbao/anaconda3/envs/rllib/lib/python3.10/site-packages/wandb/sdk/interface/interface.py", line 772, in publish_output_raw
    self._publish_output_raw(o)
  File "/home/qrbao/anaconda3/envs/rllib/lib/python3.10/site-packages/wandb/sdk/interface/interface_shared.py", line 38, in _publish_output_raw
    self._publish(rec)
  File "/home/qrbao/anaconda3/envs/rllib/lib/python3.10/site-packages/wandb/sdk/interface/interface_sock.py", line 39, in _publish
    self._sock_client.send_record_publish(record)
  File "/home/qrbao/anaconda3/envs/rllib/lib/python3.10/site-packages/wandb/sdk/lib/sock_client.py", line 174, in send_record_publish
    self.send_server_request(server_req)
  File "/home/qrbao/anaconda3/envs/rllib/lib/python3.10/site-packages/wandb/sdk/lib/sock_client.py", line 154, in send_server_request
    self._send_message(msg)
  File "/home/qrbao/anaconda3/envs/rllib/lib/python3.10/site-packages/wandb/sdk/lib/sock_client.py", line 151, in _send_message
    self._sendall_with_error_handle(header + data)
  File "/home/qrbao/anaconda3/envs/rllib/lib/python3.10/site-packages/wandb/sdk/lib/sock_client.py", line 130, in _sendall_with_error_handle
    sent = self._sock.send(data)
BrokenPipeError: [Errno 32] Broken pipe
2025-07-09 14:55:41,012 ERROR   MainThread:164079 [redirect.py:_on_write():664] [no run ID] error in stderr callback
Traceback (most recent call last):
  File "/home/qrbao/anaconda3/envs/rllib/lib/python3.10/site-packages/wandb/sdk/lib/redirect.py", line 662, in _on_write
    cb(written_data)
  File "/home/qrbao/anaconda3/envs/rllib/lib/python3.10/site-packages/wandb/sdk/wandb_run.py", line 2380, in <lambda>
    lambda data: self._console_raw_callback("stderr", data),
  File "/home/qrbao/anaconda3/envs/rllib/lib/python3.10/site-packages/wandb/sdk/wandb_run.py", line 391, in wrapper
    return func(self, *args, **kwargs)
  File "/home/qrbao/anaconda3/envs/rllib/lib/python3.10/site-packages/wandb/sdk/wandb_run.py", line 449, in wrapper_fn
    return func(self, *args, **kwargs)
  File "/home/qrbao/anaconda3/envs/rllib/lib/python3.10/site-packages/wandb/sdk/wandb_run.py", line 1561, in _console_raw_callback
    self._backend.interface.publish_output_raw(name, data)
  File "/home/qrbao/anaconda3/envs/rllib/lib/python3.10/site-packages/wandb/sdk/interface/interface.py", line 772, in publish_output_raw
    self._publish_output_raw(o)
  File "/home/qrbao/anaconda3/envs/rllib/lib/python3.10/site-packages/wandb/sdk/interface/interface_shared.py", line 38, in _publish_output_raw
    self._publish(rec)
  File "/home/qrbao/anaconda3/envs/rllib/lib/python3.10/site-packages/wandb/sdk/interface/interface_sock.py", line 39, in _publish
    self._sock_client.send_record_publish(record)
  File "/home/qrbao/anaconda3/envs/rllib/lib/python3.10/site-packages/wandb/sdk/lib/sock_client.py", line 174, in send_record_publish
    self.send_server_request(server_req)
  File "/home/qrbao/anaconda3/envs/rllib/lib/python3.10/site-packages/wandb/sdk/lib/sock_client.py", line 154, in send_server_request
    self._send_message(msg)
  File "/home/qrbao/anaconda3/envs/rllib/lib/python3.10/site-packages/wandb/sdk/lib/sock_client.py", line 151, in _send_message
    self._sendall_with_error_handle(header + data)
  File "/home/qrbao/anaconda3/envs/rllib/lib/python3.10/site-packages/wandb/sdk/lib/sock_client.py", line 130, in _sendall_with_error_handle
    sent = self._sock.send(data)
BrokenPipeError: [Errno 32] Broken pipe
2025-07-09 14:55:41,013 ERROR   MainThread:164079 [redirect.py:_on_write():664] [no run ID] error in stderr callback
Traceback (most recent call last):
  File "/home/qrbao/anaconda3/envs/rllib/lib/python3.10/site-packages/wandb/sdk/lib/redirect.py", line 662, in _on_write
    cb(written_data)
  File "/home/qrbao/anaconda3/envs/rllib/lib/python3.10/site-packages/wandb/sdk/wandb_run.py", line 2380, in <lambda>
    lambda data: self._console_raw_callback("stderr", data),
  File "/home/qrbao/anaconda3/envs/rllib/lib/python3.10/site-packages/wandb/sdk/wandb_run.py", line 391, in wrapper
    return func(self, *args, **kwargs)
  File "/home/qrbao/anaconda3/envs/rllib/lib/python3.10/site-packages/wandb/sdk/wandb_run.py", line 449, in wrapper_fn
    return func(self, *args, **kwargs)
  File "/home/qrbao/anaconda3/envs/rllib/lib/python3.10/site-packages/wandb/sdk/wandb_run.py", line 1561, in _console_raw_callback
    self._backend.interface.publish_output_raw(name, data)
  File "/home/qrbao/anaconda3/envs/rllib/lib/python3.10/site-packages/wandb/sdk/interface/interface.py", line 772, in publish_output_raw
    self._publish_output_raw(o)
  File "/home/qrbao/anaconda3/envs/rllib/lib/python3.10/site-packages/wandb/sdk/interface/interface_shared.py", line 38, in _publish_output_raw
    self._publish(rec)
  File "/home/qrbao/anaconda3/envs/rllib/lib/python3.10/site-packages/wandb/sdk/interface/interface_sock.py", line 39, in _publish
    self._sock_client.send_record_publish(record)
  File "/home/qrbao/anaconda3/envs/rllib/lib/python3.10/site-packages/wandb/sdk/lib/sock_client.py", line 174, in send_record_publish
    self.send_server_request(server_req)
  File "/home/qrbao/anaconda3/envs/rllib/lib/python3.10/site-packages/wandb/sdk/lib/sock_client.py", line 154, in send_server_request
    self._send_message(msg)
  File "/home/qrbao/anaconda3/envs/rllib/lib/python3.10/site-packages/wandb/sdk/lib/sock_client.py", line 151, in _send_message
    self._sendall_with_error_handle(header + data)
  File "/home/qrbao/anaconda3/envs/rllib/lib/python3.10/site-packages/wandb/sdk/lib/sock_client.py", line 130, in _sendall_with_error_handle
    sent = self._sock.send(data)
BrokenPipeError: [Errno 32] Broken pipe
2025-07-09 14:55:41,013 ERROR   MainThread:164079 [redirect.py:_on_write():664] [no run ID] error in stderr callback
Traceback (most recent call last):
  File "/home/qrbao/anaconda3/envs/rllib/lib/python3.10/site-packages/wandb/sdk/lib/redirect.py", line 662, in _on_write
    cb(written_data)
  File "/home/qrbao/anaconda3/envs/rllib/lib/python3.10/site-packages/wandb/sdk/wandb_run.py", line 2380, in <lambda>
    lambda data: self._console_raw_callback("stderr", data),
  File "/home/qrbao/anaconda3/envs/rllib/lib/python3.10/site-packages/wandb/sdk/wandb_run.py", line 391, in wrapper
    return func(self, *args, **kwargs)
  File "/home/qrbao/anaconda3/envs/rllib/lib/python3.10/site-packages/wandb/sdk/wandb_run.py", line 449, in wrapper_fn
    return func(self, *args, **kwargs)
  File "/home/qrbao/anaconda3/envs/rllib/lib/python3.10/site-packages/wandb/sdk/wandb_run.py", line 1561, in _console_raw_callback
    self._backend.interface.publish_output_raw(name, data)
  File "/home/qrbao/anaconda3/envs/rllib/lib/python3.10/site-packages/wandb/sdk/interface/interface.py", line 772, in publish_output_raw
    self._publish_output_raw(o)
  File "/home/qrbao/anaconda3/envs/rllib/lib/python3.10/site-packages/wandb/sdk/interface/interface_shared.py", line 38, in _publish_output_raw
    self._publish(rec)
  File "/home/qrbao/anaconda3/envs/rllib/lib/python3.10/site-packages/wandb/sdk/interface/interface_sock.py", line 39, in _publish
    self._sock_client.send_record_publish(record)
  File "/home/qrbao/anaconda3/envs/rllib/lib/python3.10/site-packages/wandb/sdk/lib/sock_client.py", line 174, in send_record_publish
    self.send_server_request(server_req)
  File "/home/qrbao/anaconda3/envs/rllib/lib/python3.10/site-packages/wandb/sdk/lib/sock_client.py", line 154, in send_server_request
    self._send_message(msg)
  File "/home/qrbao/anaconda3/envs/rllib/lib/python3.10/site-packages/wandb/sdk/lib/sock_client.py", line 151, in _send_message
    self._sendall_with_error_handle(header + data)
  File "/home/qrbao/anaconda3/envs/rllib/lib/python3.10/site-packages/wandb/sdk/lib/sock_client.py", line 130, in _sendall_with_error_handle
    sent = self._sock.send(data)
BrokenPipeError: [Errno 32] Broken pipe
2025-07-09 14:55:41,013 ERROR   MainThread:164079 [redirect.py:_on_write():664] [no run ID] error in stderr callback
Traceback (most recent call last):
  File "/home/qrbao/anaconda3/envs/rllib/lib/python3.10/site-packages/wandb/sdk/lib/redirect.py", line 662, in _on_write
    cb(written_data)
  File "/home/qrbao/anaconda3/envs/rllib/lib/python3.10/site-packages/wandb/sdk/wandb_run.py", line 2380, in <lambda>
    lambda data: self._console_raw_callback("stderr", data),
  File "/home/qrbao/anaconda3/envs/rllib/lib/python3.10/site-packages/wandb/sdk/wandb_run.py", line 391, in wrapper
    return func(self, *args, **kwargs)
  File "/home/qrbao/anaconda3/envs/rllib/lib/python3.10/site-packages/wandb/sdk/wandb_run.py", line 449, in wrapper_fn
    return func(self, *args, **kwargs)
  File "/home/qrbao/anaconda3/envs/rllib/lib/python3.10/site-packages/wandb/sdk/wandb_run.py", line 1561, in _console_raw_callback
    self._backend.interface.publish_output_raw(name, data)
  File "/home/qrbao/anaconda3/envs/rllib/lib/python3.10/site-packages/wandb/sdk/interface/interface.py", line 772, in publish_output_raw
    self._publish_output_raw(o)
  File "/home/qrbao/anaconda3/envs/rllib/lib/python3.10/site-packages/wandb/sdk/interface/interface_shared.py", line 38, in _publish_output_raw
    self._publish(rec)
  File "/home/qrbao/anaconda3/envs/rllib/lib/python3.10/site-packages/wandb/sdk/interface/interface_sock.py", line 39, in _publish
    self._sock_client.send_record_publish(record)
  File "/home/qrbao/anaconda3/envs/rllib/lib/python3.10/site-packages/wandb/sdk/lib/sock_client.py", line 174, in send_record_publish
    self.send_server_request(server_req)
  File "/home/qrbao/anaconda3/envs/rllib/lib/python3.10/site-packages/wandb/sdk/lib/sock_client.py", line 154, in send_server_request
    self._send_message(msg)
  File "/home/qrbao/anaconda3/envs/rllib/lib/python3.10/site-packages/wandb/sdk/lib/sock_client.py", line 151, in _send_message
    self._sendall_with_error_handle(header + data)
  File "/home/qrbao/anaconda3/envs/rllib/lib/python3.10/site-packages/wandb/sdk/lib/sock_client.py", line 130, in _sendall_with_error_handle
    sent = self._sock.send(data)
BrokenPipeError: [Errno 32] Broken pipe
2025-07-09 14:55:41,013 ERROR   MainThread:164079 [redirect.py:_on_write():664] [no run ID] error in stderr callback
Traceback (most recent call last):
  File "/home/qrbao/anaconda3/envs/rllib/lib/python3.10/site-packages/wandb/sdk/lib/redirect.py", line 662, in _on_write
    cb(written_data)
  File "/home/qrbao/anaconda3/envs/rllib/lib/python3.10/site-packages/wandb/sdk/wandb_run.py", line 2380, in <lambda>
    lambda data: self._console_raw_callback("stderr", data),
  File "/home/qrbao/anaconda3/envs/rllib/lib/python3.10/site-packages/wandb/sdk/wandb_run.py", line 391, in wrapper
    return func(self, *args, **kwargs)
  File "/home/qrbao/anaconda3/envs/rllib/lib/python3.10/site-packages/wandb/sdk/wandb_run.py", line 449, in wrapper_fn
    return func(self, *args, **kwargs)
  File "/home/qrbao/anaconda3/envs/rllib/lib/python3.10/site-packages/wandb/sdk/wandb_run.py", line 1561, in _console_raw_callback
    self._backend.interface.publish_output_raw(name, data)
  File "/home/qrbao/anaconda3/envs/rllib/lib/python3.10/site-packages/wandb/sdk/interface/interface.py", line 772, in publish_output_raw
    self._publish_output_raw(o)
  File "/home/qrbao/anaconda3/envs/rllib/lib/python3.10/site-packages/wandb/sdk/interface/interface_shared.py", line 38, in _publish_output_raw
    self._publish(rec)
  File "/home/qrbao/anaconda3/envs/rllib/lib/python3.10/site-packages/wandb/sdk/interface/interface_sock.py", line 39, in _publish
    self._sock_client.send_record_publish(record)
  File "/home/qrbao/anaconda3/envs/rllib/lib/python3.10/site-packages/wandb/sdk/lib/sock_client.py", line 174, in send_record_publish
    self.send_server_request(server_req)
  File "/home/qrbao/anaconda3/envs/rllib/lib/python3.10/site-packages/wandb/sdk/lib/sock_client.py", line 154, in send_server_request
    self._send_message(msg)
  File "/home/qrbao/anaconda3/envs/rllib/lib/python3.10/site-packages/wandb/sdk/lib/sock_client.py", line 151, in _send_message
    self._sendall_with_error_handle(header + data)
  File "/home/qrbao/anaconda3/envs/rllib/lib/python3.10/site-packages/wandb/sdk/lib/sock_client.py", line 130, in _sendall_with_error_handle
    sent = self._sock.send(data)
BrokenPipeError: [Errno 32] Broken pipe
2025-07-09 14:55:41,013 ERROR   MainThread:164079 [redirect.py:_on_write():664] [no run ID] error in stderr callback
Traceback (most recent call last):
  File "/home/qrbao/anaconda3/envs/rllib/lib/python3.10/site-packages/wandb/sdk/lib/redirect.py", line 662, in _on_write
    cb(written_data)
  File "/home/qrbao/anaconda3/envs/rllib/lib/python3.10/site-packages/wandb/sdk/wandb_run.py", line 2380, in <lambda>
    lambda data: self._console_raw_callback("stderr", data),
  File "/home/qrbao/anaconda3/envs/rllib/lib/python3.10/site-packages/wandb/sdk/wandb_run.py", line 391, in wrapper
    return func(self, *args, **kwargs)
  File "/home/qrbao/anaconda3/envs/rllib/lib/python3.10/site-packages/wandb/sdk/wandb_run.py", line 449, in wrapper_fn
    return func(self, *args, **kwargs)
  File "/home/qrbao/anaconda3/envs/rllib/lib/python3.10/site-packages/wandb/sdk/wandb_run.py", line 1561, in _console_raw_callback
    self._backend.interface.publish_output_raw(name, data)
  File "/home/qrbao/anaconda3/envs/rllib/lib/python3.10/site-packages/wandb/sdk/interface/interface.py", line 772, in publish_output_raw
    self._publish_output_raw(o)
  File "/home/qrbao/anaconda3/envs/rllib/lib/python3.10/site-packages/wandb/sdk/interface/interface_shared.py", line 38, in _publish_output_raw
    self._publish(rec)
  File "/home/qrbao/anaconda3/envs/rllib/lib/python3.10/site-packages/wandb/sdk/interface/interface_sock.py", line 39, in _publish
    self._sock_client.send_record_publish(record)
  File "/home/qrbao/anaconda3/envs/rllib/lib/python3.10/site-packages/wandb/sdk/lib/sock_client.py", line 174, in send_record_publish
    self.send_server_request(server_req)
  File "/home/qrbao/anaconda3/envs/rllib/lib/python3.10/site-packages/wandb/sdk/lib/sock_client.py", line 154, in send_server_request
    self._send_message(msg)
  File "/home/qrbao/anaconda3/envs/rllib/lib/python3.10/site-packages/wandb/sdk/lib/sock_client.py", line 151, in _send_message
    self._sendall_with_error_handle(header + data)
  File "/home/qrbao/anaconda3/envs/rllib/lib/python3.10/site-packages/wandb/sdk/lib/sock_client.py", line 130, in _sendall_with_error_handle
    sent = self._sock.send(data)
BrokenPipeError: [Errno 32] Broken pipe
2025-07-09 14:55:41,013 ERROR   MainThread:164079 [redirect.py:_on_write():664] [no run ID] error in stderr callback
Traceback (most recent call last):
  File "/home/qrbao/anaconda3/envs/rllib/lib/python3.10/site-packages/wandb/sdk/lib/redirect.py", line 662, in _on_write
    cb(written_data)
  File "/home/qrbao/anaconda3/envs/rllib/lib/python3.10/site-packages/wandb/sdk/wandb_run.py", line 2380, in <lambda>
    lambda data: self._console_raw_callback("stderr", data),
  File "/home/qrbao/anaconda3/envs/rllib/lib/python3.10/site-packages/wandb/sdk/wandb_run.py", line 391, in wrapper
    return func(self, *args, **kwargs)
  File "/home/qrbao/anaconda3/envs/rllib/lib/python3.10/site-packages/wandb/sdk/wandb_run.py", line 449, in wrapper_fn
    return func(self, *args, **kwargs)
  File "/home/qrbao/anaconda3/envs/rllib/lib/python3.10/site-packages/wandb/sdk/wandb_run.py", line 1561, in _console_raw_callback
    self._backend.interface.publish_output_raw(name, data)
  File "/home/qrbao/anaconda3/envs/rllib/lib/python3.10/site-packages/wandb/sdk/interface/interface.py", line 772, in publish_output_raw
    self._publish_output_raw(o)
  File "/home/qrbao/anaconda3/envs/rllib/lib/python3.10/site-packages/wandb/sdk/interface/interface_shared.py", line 38, in _publish_output_raw
    self._publish(rec)
  File "/home/qrbao/anaconda3/envs/rllib/lib/python3.10/site-packages/wandb/sdk/interface/interface_sock.py", line 39, in _publish
    self._sock_client.send_record_publish(record)
  File "/home/qrbao/anaconda3/envs/rllib/lib/python3.10/site-packages/wandb/sdk/lib/sock_client.py", line 174, in send_record_publish
    self.send_server_request(server_req)
  File "/home/qrbao/anaconda3/envs/rllib/lib/python3.10/site-packages/wandb/sdk/lib/sock_client.py", line 154, in send_server_request
    self._send_message(msg)
  File "/home/qrbao/anaconda3/envs/rllib/lib/python3.10/site-packages/wandb/sdk/lib/sock_client.py", line 151, in _send_message
    self._sendall_with_error_handle(header + data)
  File "/home/qrbao/anaconda3/envs/rllib/lib/python3.10/site-packages/wandb/sdk/lib/sock_client.py", line 130, in _sendall_with_error_handle
    sent = self._sock.send(data)
BrokenPipeError: [Errno 32] Broken pipe
2025-07-09 14:55:41,013 ERROR   MainThread:164079 [redirect.py:_on_write():664] [no run ID] error in stderr callback
Traceback (most recent call last):
  File "/home/qrbao/anaconda3/envs/rllib/lib/python3.10/site-packages/wandb/sdk/lib/redirect.py", line 662, in _on_write
    cb(written_data)
  File "/home/qrbao/anaconda3/envs/rllib/lib/python3.10/site-packages/wandb/sdk/wandb_run.py", line 2380, in <lambda>
    lambda data: self._console_raw_callback("stderr", data),
  File "/home/qrbao/anaconda3/envs/rllib/lib/python3.10/site-packages/wandb/sdk/wandb_run.py", line 391, in wrapper
    return func(self, *args, **kwargs)
  File "/home/qrbao/anaconda3/envs/rllib/lib/python3.10/site-packages/wandb/sdk/wandb_run.py", line 449, in wrapper_fn
    return func(self, *args, **kwargs)
  File "/home/qrbao/anaconda3/envs/rllib/lib/python3.10/site-packages/wandb/sdk/wandb_run.py", line 1561, in _console_raw_callback
    self._backend.interface.publish_output_raw(name, data)
  File "/home/qrbao/anaconda3/envs/rllib/lib/python3.10/site-packages/wandb/sdk/interface/interface.py", line 772, in publish_output_raw
    self._publish_output_raw(o)
  File "/home/qrbao/anaconda3/envs/rllib/lib/python3.10/site-packages/wandb/sdk/interface/interface_shared.py", line 38, in _publish_output_raw
    self._publish(rec)
  File "/home/qrbao/anaconda3/envs/rllib/lib/python3.10/site-packages/wandb/sdk/interface/interface_sock.py", line 39, in _publish
    self._sock_client.send_record_publish(record)
  File "/home/qrbao/anaconda3/envs/rllib/lib/python3.10/site-packages/wandb/sdk/lib/sock_client.py", line 174, in send_record_publish
    self.send_server_request(server_req)
  File "/home/qrbao/anaconda3/envs/rllib/lib/python3.10/site-packages/wandb/sdk/lib/sock_client.py", line 154, in send_server_request
    self._send_message(msg)
  File "/home/qrbao/anaconda3/envs/rllib/lib/python3.10/site-packages/wandb/sdk/lib/sock_client.py", line 151, in _send_message
    self._sendall_with_error_handle(header + data)
  File "/home/qrbao/anaconda3/envs/rllib/lib/python3.10/site-packages/wandb/sdk/lib/sock_client.py", line 130, in _sendall_with_error_handle
    sent = self._sock.send(data)
BrokenPipeError: [Errno 32] Broken pipe
