2025-07-01 15:26:16,734 INFO    MainThread:2033177 [wandb_init.py:setup_run_log_directory():703] Logging user logs to /home/qrbao/Documents/code4/rllib/mycode/wandb/run-20250701_152616-9py54yuk/logs/debug.log
2025-07-01 15:26:16,734 INFO    MainThread:2033177 [wandb_init.py:setup_run_log_directory():704] Logging internal logs to /home/qrbao/Documents/code4/rllib/mycode/wandb/run-20250701_152616-9py54yuk/logs/debug-internal.log
2025-07-01 15:26:16,734 INFO    MainThread:2033177 [wandb_init.py:init():831] calling init triggers
2025-07-01 15:26:16,734 INFO    MainThread:2033177 [wandb_init.py:init():836] wandb.init called with sweep_config: {}
config: {'algo': 'PPO', 'enable_new_api_stack': True, 'framework': 'torch', 'env': None, 'num_env_runners': None, 'num_envs_per_env_runner': None, 'num_agents': 5, 'evaluation_num_env_runners': 0, 'evaluation_interval': 0, 'evaluation_duration': 10, 'evaluation_duration_unit': 'episodes', 'evaluation_parallel_to_training': False, 'output': None, 'log_level': None, 'no_tune': False, 'num_samples': 1, 'max_concurrent_trials': None, 'verbose': 2, 'checkpoint_freq': 1, 'checkpoint_at_end': True, 'wandb_key': 'fdd7656f474bba144dea1887bcdab534bc7df647', 'wandb_project': 'waterworld-v4', 'wandb_run_name': None, 'stop_reward': 200.0, 'stop_iters': 200, 'stop_timesteps': 1000000, 'as_test': False, 'as_release_test': False, 'num_learners': None, 'num_cpus_per_learner': None, 'num_gpus_per_learner': None, 'num_aggregator_actors_per_learner': None, 'num_cpus': 0, 'local_mode': False, 'num_gpus': None, 'n_predators': 2, 'n_preys': 3, 'use_onnx_for_inference': False, 'explore_during_inference': False, 'num_episodes_during_inference': 10, '_wandb': {}}
2025-07-01 15:26:18,788 INFO    MainThread:2033177 [wandb_init.py:init():872] starting backend
2025-07-01 15:26:18,788 INFO    MainThread:2033177 [wandb_init.py:init():875] sending inform_init request
2025-07-01 15:26:18,789 INFO    MainThread:2033177 [wandb_init.py:init():883] backend started and connected
2025-07-01 15:26:18,792 INFO    MainThread:2033177 [wandb_run.py:_label_probe_notebook():1299] probe notebook
2025-07-01 15:26:18,840 INFO    MainThread:2033177 [wandb_init.py:init():956] updated telemetry
2025-07-01 15:26:18,841 INFO    MainThread:2033177 [wandb_init.py:init():980] communicating run to backend with 90.0 second timeout
2025-07-01 15:26:19,438 INFO    MainThread:2033177 [wandb_init.py:init():1032] starting run threads in backend
2025-07-01 15:26:19,489 INFO    MainThread:2033177 [wandb_run.py:_console_start():2453] atexit reg
2025-07-01 15:26:19,490 INFO    MainThread:2033177 [wandb_run.py:_redirect():2301] redirect: wrap_raw
2025-07-01 15:26:19,490 INFO    MainThread:2033177 [wandb_run.py:_redirect():2370] Wrapping output streams.
2025-07-01 15:26:19,490 INFO    MainThread:2033177 [wandb_run.py:_redirect():2393] Redirects installed.
2025-07-01 15:26:19,490 INFO    MainThread:2033177 [wandb_init.py:init():1078] run started, returning control to user process
2025-07-01 15:26:45,339 WARNING MsgRouterThr:2033177 [router.py:message_loop():63] [no run ID] message_loop has been closed
Traceback (most recent call last):
  File "/home/qrbao/anaconda3/envs/rllib/lib/python3.10/site-packages/wandb/sdk/interface/router_sock.py", line 27, in _read_message
    return self._sock_client.read_server_response(timeout=1)
  File "/home/qrbao/anaconda3/envs/rllib/lib/python3.10/site-packages/wandb/sdk/lib/sock_client.py", line 235, in read_server_response
    data = self._read_packet_bytes(timeout=timeout)
  File "/home/qrbao/anaconda3/envs/rllib/lib/python3.10/site-packages/wandb/sdk/lib/sock_client.py", line 220, in _read_packet_bytes
    raise SockClientClosedError
wandb.sdk.lib.sock_client.SockClientClosedError

The above exception was the direct cause of the following exception:

Traceback (most recent call last):
  File "/home/qrbao/anaconda3/envs/rllib/lib/python3.10/site-packages/wandb/sdk/interface/router.py", line 56, in message_loop
    msg = self._read_message()
  File "/home/qrbao/anaconda3/envs/rllib/lib/python3.10/site-packages/wandb/sdk/interface/router_sock.py", line 29, in _read_message
    raise MessageRouterClosedError from e
wandb.sdk.interface.router.MessageRouterClosedError
2025-07-01 15:26:45,340 INFO    MsgRouterThr:2033177 [mailbox.py:close():129] [no run ID] Closing mailbox, abandoning 2 handles.
2025-07-01 15:26:45,379 ERROR   MainThread:2033177 [redirect.py:_on_write():664] [no run ID] error in stderr callback
Traceback (most recent call last):
  File "/home/qrbao/anaconda3/envs/rllib/lib/python3.10/site-packages/wandb/sdk/lib/redirect.py", line 662, in _on_write
    cb(written_data)
  File "/home/qrbao/anaconda3/envs/rllib/lib/python3.10/site-packages/wandb/sdk/wandb_run.py", line 2380, in <lambda>
    lambda data: self._console_raw_callback("stderr", data),
  File "/home/qrbao/anaconda3/envs/rllib/lib/python3.10/site-packages/wandb/sdk/wandb_run.py", line 391, in wrapper
    return func(self, *args, **kwargs)
  File "/home/qrbao/anaconda3/envs/rllib/lib/python3.10/site-packages/wandb/sdk/wandb_run.py", line 449, in wrapper_fn
    return func(self, *args, **kwargs)
  File "/home/qrbao/anaconda3/envs/rllib/lib/python3.10/site-packages/wandb/sdk/wandb_run.py", line 1561, in _console_raw_callback
    self._backend.interface.publish_output_raw(name, data)
  File "/home/qrbao/anaconda3/envs/rllib/lib/python3.10/site-packages/wandb/sdk/interface/interface.py", line 772, in publish_output_raw
    self._publish_output_raw(o)
  File "/home/qrbao/anaconda3/envs/rllib/lib/python3.10/site-packages/wandb/sdk/interface/interface_shared.py", line 38, in _publish_output_raw
    self._publish(rec)
  File "/home/qrbao/anaconda3/envs/rllib/lib/python3.10/site-packages/wandb/sdk/interface/interface_sock.py", line 39, in _publish
    self._sock_client.send_record_publish(record)
  File "/home/qrbao/anaconda3/envs/rllib/lib/python3.10/site-packages/wandb/sdk/lib/sock_client.py", line 174, in send_record_publish
    self.send_server_request(server_req)
  File "/home/qrbao/anaconda3/envs/rllib/lib/python3.10/site-packages/wandb/sdk/lib/sock_client.py", line 154, in send_server_request
    self._send_message(msg)
  File "/home/qrbao/anaconda3/envs/rllib/lib/python3.10/site-packages/wandb/sdk/lib/sock_client.py", line 151, in _send_message
    self._sendall_with_error_handle(header + data)
  File "/home/qrbao/anaconda3/envs/rllib/lib/python3.10/site-packages/wandb/sdk/lib/sock_client.py", line 130, in _sendall_with_error_handle
    sent = self._sock.send(data)
BrokenPipeError: [Errno 32] Broken pipe
2025-07-01 15:26:45,381 ERROR   MainThread:2033177 [redirect.py:_on_write():664] [no run ID] error in stdout callback
Traceback (most recent call last):
  File "/home/qrbao/anaconda3/envs/rllib/lib/python3.10/site-packages/wandb/sdk/lib/redirect.py", line 662, in _on_write
    cb(written_data)
  File "/home/qrbao/anaconda3/envs/rllib/lib/python3.10/site-packages/wandb/sdk/wandb_run.py", line 2374, in <lambda>
    lambda data: self._console_raw_callback("stdout", data),
  File "/home/qrbao/anaconda3/envs/rllib/lib/python3.10/site-packages/wandb/sdk/wandb_run.py", line 391, in wrapper
    return func(self, *args, **kwargs)
  File "/home/qrbao/anaconda3/envs/rllib/lib/python3.10/site-packages/wandb/sdk/wandb_run.py", line 449, in wrapper_fn
    return func(self, *args, **kwargs)
  File "/home/qrbao/anaconda3/envs/rllib/lib/python3.10/site-packages/wandb/sdk/wandb_run.py", line 1561, in _console_raw_callback
    self._backend.interface.publish_output_raw(name, data)
  File "/home/qrbao/anaconda3/envs/rllib/lib/python3.10/site-packages/wandb/sdk/interface/interface.py", line 772, in publish_output_raw
    self._publish_output_raw(o)
  File "/home/qrbao/anaconda3/envs/rllib/lib/python3.10/site-packages/wandb/sdk/interface/interface_shared.py", line 38, in _publish_output_raw
    self._publish(rec)
  File "/home/qrbao/anaconda3/envs/rllib/lib/python3.10/site-packages/wandb/sdk/interface/interface_sock.py", line 39, in _publish
    self._sock_client.send_record_publish(record)
  File "/home/qrbao/anaconda3/envs/rllib/lib/python3.10/site-packages/wandb/sdk/lib/sock_client.py", line 174, in send_record_publish
    self.send_server_request(server_req)
  File "/home/qrbao/anaconda3/envs/rllib/lib/python3.10/site-packages/wandb/sdk/lib/sock_client.py", line 154, in send_server_request
    self._send_message(msg)
  File "/home/qrbao/anaconda3/envs/rllib/lib/python3.10/site-packages/wandb/sdk/lib/sock_client.py", line 151, in _send_message
    self._sendall_with_error_handle(header + data)
  File "/home/qrbao/anaconda3/envs/rllib/lib/python3.10/site-packages/wandb/sdk/lib/sock_client.py", line 130, in _sendall_with_error_handle
    sent = self._sock.send(data)
BrokenPipeError: [Errno 32] Broken pipe
2025-07-01 15:26:45,382 ERROR   MainThread:2033177 [redirect.py:_on_write():664] [no run ID] error in stdout callback
Traceback (most recent call last):
  File "/home/qrbao/anaconda3/envs/rllib/lib/python3.10/site-packages/wandb/sdk/lib/redirect.py", line 662, in _on_write
    cb(written_data)
  File "/home/qrbao/anaconda3/envs/rllib/lib/python3.10/site-packages/wandb/sdk/wandb_run.py", line 2374, in <lambda>
    lambda data: self._console_raw_callback("stdout", data),
  File "/home/qrbao/anaconda3/envs/rllib/lib/python3.10/site-packages/wandb/sdk/wandb_run.py", line 391, in wrapper
    return func(self, *args, **kwargs)
  File "/home/qrbao/anaconda3/envs/rllib/lib/python3.10/site-packages/wandb/sdk/wandb_run.py", line 449, in wrapper_fn
    return func(self, *args, **kwargs)
  File "/home/qrbao/anaconda3/envs/rllib/lib/python3.10/site-packages/wandb/sdk/wandb_run.py", line 1561, in _console_raw_callback
    self._backend.interface.publish_output_raw(name, data)
  File "/home/qrbao/anaconda3/envs/rllib/lib/python3.10/site-packages/wandb/sdk/interface/interface.py", line 772, in publish_output_raw
    self._publish_output_raw(o)
  File "/home/qrbao/anaconda3/envs/rllib/lib/python3.10/site-packages/wandb/sdk/interface/interface_shared.py", line 38, in _publish_output_raw
    self._publish(rec)
  File "/home/qrbao/anaconda3/envs/rllib/lib/python3.10/site-packages/wandb/sdk/interface/interface_sock.py", line 39, in _publish
    self._sock_client.send_record_publish(record)
  File "/home/qrbao/anaconda3/envs/rllib/lib/python3.10/site-packages/wandb/sdk/lib/sock_client.py", line 174, in send_record_publish
    self.send_server_request(server_req)
  File "/home/qrbao/anaconda3/envs/rllib/lib/python3.10/site-packages/wandb/sdk/lib/sock_client.py", line 154, in send_server_request
    self._send_message(msg)
  File "/home/qrbao/anaconda3/envs/rllib/lib/python3.10/site-packages/wandb/sdk/lib/sock_client.py", line 151, in _send_message
    self._sendall_with_error_handle(header + data)
  File "/home/qrbao/anaconda3/envs/rllib/lib/python3.10/site-packages/wandb/sdk/lib/sock_client.py", line 130, in _sendall_with_error_handle
    sent = self._sock.send(data)
BrokenPipeError: [Errno 32] Broken pipe
2025-07-01 15:26:57,386 ERROR   MainThread:2033177 [redirect.py:_on_write():664] [no run ID] error in stderr callback
Traceback (most recent call last):
  File "/home/qrbao/anaconda3/envs/rllib/lib/python3.10/site-packages/IPython/core/interactiveshell.py", line 3579, in run_code
    exec(code_obj, self.user_global_ns, self.user_ns)
  File "/tmp/ipykernel_2033177/1832976043.py", line 3, in <module>
    run_rllib_example_script_experiment(base_config, args, keep_ray_up=True)
  File "/home/qrbao/anaconda3/envs/rllib/lib/python3.10/site-packages/ray/rllib/utils/test_utils.py", line 1342, in run_rllib_example_script_experiment
    ).fit()
  File "/home/qrbao/anaconda3/envs/rllib/lib/python3.10/site-packages/ray/tune/tuner.py", line 345, in fit
    return self._local_tuner.fit()
  File "/home/qrbao/anaconda3/envs/rllib/lib/python3.10/site-packages/ray/tune/impl/tuner_internal.py", line 506, in fit
    analysis = self._fit_internal(trainable, param_space)
  File "/home/qrbao/anaconda3/envs/rllib/lib/python3.10/site-packages/ray/tune/impl/tuner_internal.py", line 622, in _fit_internal
    analysis = run(
  File "/home/qrbao/anaconda3/envs/rllib/lib/python3.10/site-packages/ray/tune/tune.py", line 1026, in run
    runner.cleanup()
  File "/home/qrbao/anaconda3/envs/rllib/lib/python3.10/site-packages/ray/tune/execution/tune_controller.py", line 1976, in cleanup
    self.end_experiment_callbacks()
  File "/home/qrbao/anaconda3/envs/rllib/lib/python3.10/site-packages/ray/tune/execution/tune_controller.py", line 296, in end_experiment_callbacks
    self._callbacks.on_experiment_end(trials=self._trials)
  File "/home/qrbao/anaconda3/envs/rllib/lib/python3.10/site-packages/ray/tune/callback.py", line 430, in on_experiment_end
    callback.on_experiment_end(**info)
  File "/home/qrbao/anaconda3/envs/rllib/lib/python3.10/site-packages/ray/air/integrations/wandb.py", line 739, in on_experiment_end
    self._cleanup_logging_actors(timeout=self._upload_timeout, kill_on_timeout=True)
  File "/home/qrbao/anaconda3/envs/rllib/lib/python3.10/site-packages/ray/air/integrations/wandb.py", line 726, in _cleanup_logging_actors
    done, remaining = ray.wait(futures, num_returns=len(futures), timeout=timeout)
  File "/home/qrbao/anaconda3/envs/rllib/lib/python3.10/site-packages/ray/_private/auto_init_hook.py", line 22, in auto_init_wrapper
    return fn(*args, **kwargs)
  File "/home/qrbao/anaconda3/envs/rllib/lib/python3.10/site-packages/ray/_private/client_mode_hook.py", line 104, in wrapper
    return func(*args, **kwargs)
  File "/home/qrbao/anaconda3/envs/rllib/lib/python3.10/site-packages/ray/_private/worker.py", line 3080, in wait
    ready_ids, remaining_ids = worker.core_worker.wait(
  File "python/ray/_raylet.pyx", line 3480, in ray._raylet.CoreWorker.wait
  File "python/ray/includes/common.pxi", line 101, in ray._raylet.check_status
  File "python/ray/_raylet.pyx", line 854, in ray._raylet.raise_sys_exit_with_custom_error_message
SystemExit: 1

During handling of the above exception, another exception occurred:

Traceback (most recent call last):
  File "/home/qrbao/anaconda3/envs/rllib/lib/python3.10/site-packages/wandb/sdk/lib/redirect.py", line 662, in _on_write
    cb(written_data)
  File "/home/qrbao/anaconda3/envs/rllib/lib/python3.10/site-packages/wandb/sdk/wandb_run.py", line 2380, in <lambda>
    lambda data: self._console_raw_callback("stderr", data),
  File "/home/qrbao/anaconda3/envs/rllib/lib/python3.10/site-packages/wandb/sdk/wandb_run.py", line 391, in wrapper
    return func(self, *args, **kwargs)
  File "/home/qrbao/anaconda3/envs/rllib/lib/python3.10/site-packages/wandb/sdk/wandb_run.py", line 449, in wrapper_fn
    return func(self, *args, **kwargs)
  File "/home/qrbao/anaconda3/envs/rllib/lib/python3.10/site-packages/wandb/sdk/wandb_run.py", line 1561, in _console_raw_callback
    self._backend.interface.publish_output_raw(name, data)
  File "/home/qrbao/anaconda3/envs/rllib/lib/python3.10/site-packages/wandb/sdk/interface/interface.py", line 772, in publish_output_raw
    self._publish_output_raw(o)
  File "/home/qrbao/anaconda3/envs/rllib/lib/python3.10/site-packages/wandb/sdk/interface/interface_shared.py", line 38, in _publish_output_raw
    self._publish(rec)
  File "/home/qrbao/anaconda3/envs/rllib/lib/python3.10/site-packages/wandb/sdk/interface/interface_sock.py", line 39, in _publish
    self._sock_client.send_record_publish(record)
  File "/home/qrbao/anaconda3/envs/rllib/lib/python3.10/site-packages/wandb/sdk/lib/sock_client.py", line 174, in send_record_publish
    self.send_server_request(server_req)
  File "/home/qrbao/anaconda3/envs/rllib/lib/python3.10/site-packages/wandb/sdk/lib/sock_client.py", line 154, in send_server_request
    self._send_message(msg)
  File "/home/qrbao/anaconda3/envs/rllib/lib/python3.10/site-packages/wandb/sdk/lib/sock_client.py", line 151, in _send_message
    self._sendall_with_error_handle(header + data)
  File "/home/qrbao/anaconda3/envs/rllib/lib/python3.10/site-packages/wandb/sdk/lib/sock_client.py", line 130, in _sendall_with_error_handle
    sent = self._sock.send(data)
BrokenPipeError: [Errno 32] Broken pipe
