2025-07-01 21:45:41,552 INFO    MainThread:3300374 [wandb_setup.py:_flush():81] Current SDK version is 0.20.1
2025-07-01 21:45:41,552 INFO    MainThread:3300374 [wandb_setup.py:_flush():81] Configure stats pid to 3300374
2025-07-01 21:45:41,552 INFO    MainThread:3300374 [wandb_setup.py:_flush():81] Loading settings from /home/qrbao/.config/wandb/settings
2025-07-01 21:45:41,552 INFO    MainThread:3300374 [wandb_setup.py:_flush():81] Loading settings from /home/qrbao/Documents/code4/rllib/mycode/wandb/settings
2025-07-01 21:45:41,552 INFO    MainThread:3300374 [wandb_setup.py:_flush():81] Loading settings from environment variables
2025-07-01 21:45:41,553 INFO    MainThread:3300374 [wandb_init.py:setup_run_log_directory():703] Logging user logs to /home/qrbao/Documents/code4/rllib/mycode/wandb/run-20250701_214541-p2gfiwj2/logs/debug.log
2025-07-01 21:45:41,553 INFO    MainThread:3300374 [wandb_init.py:setup_run_log_directory():704] Logging internal logs to /home/qrbao/Documents/code4/rllib/mycode/wandb/run-20250701_214541-p2gfiwj2/logs/debug-internal.log
2025-07-01 21:45:41,553 INFO    MainThread:3300374 [wandb_init.py:init():831] calling init triggers
2025-07-01 21:45:41,553 INFO    MainThread:3300374 [wandb_init.py:init():836] wandb.init called with sweep_config: {}
config: {'algo': 'PPO', 'enable_new_api_stack': True, 'framework': 'torch', 'env': None, 'num_env_runners': None, 'num_envs_per_env_runner': None, 'num_agents': 4, 'evaluation_num_env_runners': 0, 'evaluation_interval': 0, 'evaluation_duration': 10, 'evaluation_duration_unit': 'episodes', 'evaluation_parallel_to_training': False, 'output': None, 'log_level': None, 'no_tune': False, 'num_samples': 1, 'max_concurrent_trials': None, 'verbose': 2, 'checkpoint_freq': 1, 'checkpoint_at_end': True, 'wandb_key': 'fdd7656f474bba144dea1887bcdab534bc7df647', 'wandb_project': 'waterworld-v4', 'wandb_run_name': None, 'stop_reward': 200.0, 'stop_iters': 200, 'stop_timesteps': 1000000, 'as_test': False, 'as_release_test': False, 'num_learners': None, 'num_cpus_per_learner': None, 'num_gpus_per_learner': None, 'num_aggregator_actors_per_learner': None, 'num_cpus': 0, 'local_mode': False, 'num_gpus': None, 'n_predators': 2, 'n_preys': 2, 'use_onnx_for_inference': False, 'explore_during_inference': False, 'num_episodes_during_inference': 10, '_wandb': {}}
2025-07-01 21:45:41,553 INFO    MainThread:3300374 [wandb_init.py:init():872] starting backend
2025-07-01 21:45:41,768 INFO    MainThread:3300374 [wandb_init.py:init():875] sending inform_init request
2025-07-01 21:45:41,770 INFO    MainThread:3300374 [wandb_init.py:init():883] backend started and connected
2025-07-01 21:45:41,771 INFO    MainThread:3300374 [wandb_init.py:init():956] updated telemetry
2025-07-01 21:45:41,772 INFO    MainThread:3300374 [wandb_init.py:init():980] communicating run to backend with 90.0 second timeout
2025-07-01 21:45:42,514 INFO    MainThread:3300374 [wandb_init.py:init():1032] starting run threads in backend
2025-07-01 21:45:42,561 INFO    MainThread:3300374 [wandb_run.py:_console_start():2453] atexit reg
2025-07-01 21:45:42,561 INFO    MainThread:3300374 [wandb_run.py:_redirect():2301] redirect: wrap_raw
2025-07-01 21:45:42,561 INFO    MainThread:3300374 [wandb_run.py:_redirect():2370] Wrapping output streams.
2025-07-01 21:45:42,561 INFO    MainThread:3300374 [wandb_run.py:_redirect():2393] Redirects installed.
2025-07-01 21:45:42,562 INFO    MainThread:3300374 [wandb_init.py:init():1078] run started, returning control to user process
2025-07-03 12:22:09,306 WARNING MsgRouterThr:3300374 [router.py:message_loop():63] [no run ID] message_loop has been closed
Traceback (most recent call last):
  File "/home/qrbao/anaconda3/envs/rllib/lib/python3.10/site-packages/wandb/sdk/lib/sock_client.py", line 208, in _read_packet_bytes
    data = self._sock.recv(self._bufsize)
ConnectionResetError: [Errno 104] Connection reset by peer

The above exception was the direct cause of the following exception:

Traceback (most recent call last):
  File "/home/qrbao/anaconda3/envs/rllib/lib/python3.10/site-packages/wandb/sdk/interface/router_sock.py", line 27, in _read_message
    return self._sock_client.read_server_response(timeout=1)
  File "/home/qrbao/anaconda3/envs/rllib/lib/python3.10/site-packages/wandb/sdk/lib/sock_client.py", line 235, in read_server_response
    data = self._read_packet_bytes(timeout=timeout)
  File "/home/qrbao/anaconda3/envs/rllib/lib/python3.10/site-packages/wandb/sdk/lib/sock_client.py", line 212, in _read_packet_bytes
    raise SockClientClosedError from e
wandb.sdk.lib.sock_client.SockClientClosedError

The above exception was the direct cause of the following exception:

Traceback (most recent call last):
  File "/home/qrbao/anaconda3/envs/rllib/lib/python3.10/site-packages/wandb/sdk/interface/router.py", line 56, in message_loop
    msg = self._read_message()
  File "/home/qrbao/anaconda3/envs/rllib/lib/python3.10/site-packages/wandb/sdk/interface/router_sock.py", line 29, in _read_message
    raise MessageRouterClosedError from e
wandb.sdk.interface.router.MessageRouterClosedError
2025-07-03 12:22:09,339 INFO    MsgRouterThr:3300374 [mailbox.py:close():129] [no run ID] Closing mailbox, abandoning 3 handles.
2025-07-03 12:22:09,346 ERROR   MainThread:3300374 [redirect.py:_on_write():664] [no run ID] error in stdout callback
Traceback (most recent call last):
  File "/home/qrbao/anaconda3/envs/rllib/lib/python3.10/site-packages/wandb/sdk/lib/redirect.py", line 662, in _on_write
    cb(written_data)
  File "/home/qrbao/anaconda3/envs/rllib/lib/python3.10/site-packages/wandb/sdk/wandb_run.py", line 2374, in <lambda>
    lambda data: self._console_raw_callback("stdout", data),
  File "/home/qrbao/anaconda3/envs/rllib/lib/python3.10/site-packages/wandb/sdk/wandb_run.py", line 391, in wrapper
    return func(self, *args, **kwargs)
  File "/home/qrbao/anaconda3/envs/rllib/lib/python3.10/site-packages/wandb/sdk/wandb_run.py", line 449, in wrapper_fn
    return func(self, *args, **kwargs)
  File "/home/qrbao/anaconda3/envs/rllib/lib/python3.10/site-packages/wandb/sdk/wandb_run.py", line 1561, in _console_raw_callback
    self._backend.interface.publish_output_raw(name, data)
  File "/home/qrbao/anaconda3/envs/rllib/lib/python3.10/site-packages/wandb/sdk/interface/interface.py", line 772, in publish_output_raw
    self._publish_output_raw(o)
  File "/home/qrbao/anaconda3/envs/rllib/lib/python3.10/site-packages/wandb/sdk/interface/interface_shared.py", line 38, in _publish_output_raw
    self._publish(rec)
  File "/home/qrbao/anaconda3/envs/rllib/lib/python3.10/site-packages/wandb/sdk/interface/interface_sock.py", line 39, in _publish
    self._sock_client.send_record_publish(record)
  File "/home/qrbao/anaconda3/envs/rllib/lib/python3.10/site-packages/wandb/sdk/lib/sock_client.py", line 174, in send_record_publish
    self.send_server_request(server_req)
  File "/home/qrbao/anaconda3/envs/rllib/lib/python3.10/site-packages/wandb/sdk/lib/sock_client.py", line 154, in send_server_request
    self._send_message(msg)
  File "/home/qrbao/anaconda3/envs/rllib/lib/python3.10/site-packages/wandb/sdk/lib/sock_client.py", line 151, in _send_message
    self._sendall_with_error_handle(header + data)
  File "/home/qrbao/anaconda3/envs/rllib/lib/python3.10/site-packages/wandb/sdk/lib/sock_client.py", line 130, in _sendall_with_error_handle
    sent = self._sock.send(data)
BrokenPipeError: [Errno 32] Broken pipe
2025-07-03 12:22:09,372 ERROR   MainThread:3300374 [redirect.py:_on_write():664] [no run ID] error in stdout callback
Traceback (most recent call last):
  File "/home/qrbao/anaconda3/envs/rllib/lib/python3.10/site-packages/wandb/sdk/lib/redirect.py", line 662, in _on_write
    cb(written_data)
  File "/home/qrbao/anaconda3/envs/rllib/lib/python3.10/site-packages/wandb/sdk/wandb_run.py", line 2374, in <lambda>
    lambda data: self._console_raw_callback("stdout", data),
  File "/home/qrbao/anaconda3/envs/rllib/lib/python3.10/site-packages/wandb/sdk/wandb_run.py", line 391, in wrapper
    return func(self, *args, **kwargs)
  File "/home/qrbao/anaconda3/envs/rllib/lib/python3.10/site-packages/wandb/sdk/wandb_run.py", line 449, in wrapper_fn
    return func(self, *args, **kwargs)
  File "/home/qrbao/anaconda3/envs/rllib/lib/python3.10/site-packages/wandb/sdk/wandb_run.py", line 1561, in _console_raw_callback
    self._backend.interface.publish_output_raw(name, data)
  File "/home/qrbao/anaconda3/envs/rllib/lib/python3.10/site-packages/wandb/sdk/interface/interface.py", line 772, in publish_output_raw
    self._publish_output_raw(o)
  File "/home/qrbao/anaconda3/envs/rllib/lib/python3.10/site-packages/wandb/sdk/interface/interface_shared.py", line 38, in _publish_output_raw
    self._publish(rec)
  File "/home/qrbao/anaconda3/envs/rllib/lib/python3.10/site-packages/wandb/sdk/interface/interface_sock.py", line 39, in _publish
    self._sock_client.send_record_publish(record)
  File "/home/qrbao/anaconda3/envs/rllib/lib/python3.10/site-packages/wandb/sdk/lib/sock_client.py", line 174, in send_record_publish
    self.send_server_request(server_req)
  File "/home/qrbao/anaconda3/envs/rllib/lib/python3.10/site-packages/wandb/sdk/lib/sock_client.py", line 154, in send_server_request
    self._send_message(msg)
  File "/home/qrbao/anaconda3/envs/rllib/lib/python3.10/site-packages/wandb/sdk/lib/sock_client.py", line 151, in _send_message
    self._sendall_with_error_handle(header + data)
  File "/home/qrbao/anaconda3/envs/rllib/lib/python3.10/site-packages/wandb/sdk/lib/sock_client.py", line 130, in _sendall_with_error_handle
    sent = self._sock.send(data)
BrokenPipeError: [Errno 32] Broken pipe
2025-07-03 12:22:09,391 ERROR   ray_print_logs:3300374 [redirect.py:_on_write():664] [no run ID] error in stdout callback
Traceback (most recent call last):
  File "/home/qrbao/anaconda3/envs/rllib/lib/python3.10/site-packages/wandb/sdk/lib/redirect.py", line 662, in _on_write
    cb(written_data)
  File "/home/qrbao/anaconda3/envs/rllib/lib/python3.10/site-packages/wandb/sdk/wandb_run.py", line 2374, in <lambda>
    lambda data: self._console_raw_callback("stdout", data),
  File "/home/qrbao/anaconda3/envs/rllib/lib/python3.10/site-packages/wandb/sdk/wandb_run.py", line 391, in wrapper
    return func(self, *args, **kwargs)
  File "/home/qrbao/anaconda3/envs/rllib/lib/python3.10/site-packages/wandb/sdk/wandb_run.py", line 449, in wrapper_fn
    return func(self, *args, **kwargs)
  File "/home/qrbao/anaconda3/envs/rllib/lib/python3.10/site-packages/wandb/sdk/wandb_run.py", line 1561, in _console_raw_callback
    self._backend.interface.publish_output_raw(name, data)
  File "/home/qrbao/anaconda3/envs/rllib/lib/python3.10/site-packages/wandb/sdk/interface/interface.py", line 772, in publish_output_raw
    self._publish_output_raw(o)
  File "/home/qrbao/anaconda3/envs/rllib/lib/python3.10/site-packages/wandb/sdk/interface/interface_shared.py", line 38, in _publish_output_raw
    self._publish(rec)
  File "/home/qrbao/anaconda3/envs/rllib/lib/python3.10/site-packages/wandb/sdk/interface/interface_sock.py", line 39, in _publish
    self._sock_client.send_record_publish(record)
  File "/home/qrbao/anaconda3/envs/rllib/lib/python3.10/site-packages/wandb/sdk/lib/sock_client.py", line 174, in send_record_publish
    self.send_server_request(server_req)
  File "/home/qrbao/anaconda3/envs/rllib/lib/python3.10/site-packages/wandb/sdk/lib/sock_client.py", line 154, in send_server_request
    self._send_message(msg)
  File "/home/qrbao/anaconda3/envs/rllib/lib/python3.10/site-packages/wandb/sdk/lib/sock_client.py", line 151, in _send_message
    self._sendall_with_error_handle(header + data)
  File "/home/qrbao/anaconda3/envs/rllib/lib/python3.10/site-packages/wandb/sdk/lib/sock_client.py", line 130, in _sendall_with_error_handle
    sent = self._sock.send(data)
BrokenPipeError: [Errno 32] Broken pipe
2025-07-03 12:22:09,426 ERROR   ray_print_logs:3300374 [redirect.py:_on_write():664] [no run ID] error in stdout callback
Traceback (most recent call last):
  File "/home/qrbao/anaconda3/envs/rllib/lib/python3.10/site-packages/wandb/sdk/lib/redirect.py", line 662, in _on_write
    cb(written_data)
  File "/home/qrbao/anaconda3/envs/rllib/lib/python3.10/site-packages/wandb/sdk/wandb_run.py", line 2374, in <lambda>
    lambda data: self._console_raw_callback("stdout", data),
  File "/home/qrbao/anaconda3/envs/rllib/lib/python3.10/site-packages/wandb/sdk/wandb_run.py", line 391, in wrapper
    return func(self, *args, **kwargs)
  File "/home/qrbao/anaconda3/envs/rllib/lib/python3.10/site-packages/wandb/sdk/wandb_run.py", line 449, in wrapper_fn
    return func(self, *args, **kwargs)
  File "/home/qrbao/anaconda3/envs/rllib/lib/python3.10/site-packages/wandb/sdk/wandb_run.py", line 1561, in _console_raw_callback
    self._backend.interface.publish_output_raw(name, data)
  File "/home/qrbao/anaconda3/envs/rllib/lib/python3.10/site-packages/wandb/sdk/interface/interface.py", line 772, in publish_output_raw
    self._publish_output_raw(o)
  File "/home/qrbao/anaconda3/envs/rllib/lib/python3.10/site-packages/wandb/sdk/interface/interface_shared.py", line 38, in _publish_output_raw
    self._publish(rec)
  File "/home/qrbao/anaconda3/envs/rllib/lib/python3.10/site-packages/wandb/sdk/interface/interface_sock.py", line 39, in _publish
    self._sock_client.send_record_publish(record)
  File "/home/qrbao/anaconda3/envs/rllib/lib/python3.10/site-packages/wandb/sdk/lib/sock_client.py", line 174, in send_record_publish
    self.send_server_request(server_req)
  File "/home/qrbao/anaconda3/envs/rllib/lib/python3.10/site-packages/wandb/sdk/lib/sock_client.py", line 154, in send_server_request
    self._send_message(msg)
  File "/home/qrbao/anaconda3/envs/rllib/lib/python3.10/site-packages/wandb/sdk/lib/sock_client.py", line 151, in _send_message
    self._sendall_with_error_handle(header + data)
  File "/home/qrbao/anaconda3/envs/rllib/lib/python3.10/site-packages/wandb/sdk/lib/sock_client.py", line 130, in _sendall_with_error_handle
    sent = self._sock.send(data)
BrokenPipeError: [Errno 32] Broken pipe
2025-07-03 12:22:09,427 ERROR   ray_print_logs:3300374 [redirect.py:_on_write():664] [no run ID] error in stdout callback
Traceback (most recent call last):
  File "/home/qrbao/anaconda3/envs/rllib/lib/python3.10/site-packages/wandb/sdk/lib/redirect.py", line 662, in _on_write
    cb(written_data)
  File "/home/qrbao/anaconda3/envs/rllib/lib/python3.10/site-packages/wandb/sdk/wandb_run.py", line 2374, in <lambda>
    lambda data: self._console_raw_callback("stdout", data),
  File "/home/qrbao/anaconda3/envs/rllib/lib/python3.10/site-packages/wandb/sdk/wandb_run.py", line 391, in wrapper
    return func(self, *args, **kwargs)
  File "/home/qrbao/anaconda3/envs/rllib/lib/python3.10/site-packages/wandb/sdk/wandb_run.py", line 449, in wrapper_fn
    return func(self, *args, **kwargs)
  File "/home/qrbao/anaconda3/envs/rllib/lib/python3.10/site-packages/wandb/sdk/wandb_run.py", line 1561, in _console_raw_callback
    self._backend.interface.publish_output_raw(name, data)
  File "/home/qrbao/anaconda3/envs/rllib/lib/python3.10/site-packages/wandb/sdk/interface/interface.py", line 772, in publish_output_raw
    self._publish_output_raw(o)
  File "/home/qrbao/anaconda3/envs/rllib/lib/python3.10/site-packages/wandb/sdk/interface/interface_shared.py", line 38, in _publish_output_raw
    self._publish(rec)
  File "/home/qrbao/anaconda3/envs/rllib/lib/python3.10/site-packages/wandb/sdk/interface/interface_sock.py", line 39, in _publish
    self._sock_client.send_record_publish(record)
  File "/home/qrbao/anaconda3/envs/rllib/lib/python3.10/site-packages/wandb/sdk/lib/sock_client.py", line 174, in send_record_publish
    self.send_server_request(server_req)
  File "/home/qrbao/anaconda3/envs/rllib/lib/python3.10/site-packages/wandb/sdk/lib/sock_client.py", line 154, in send_server_request
    self._send_message(msg)
  File "/home/qrbao/anaconda3/envs/rllib/lib/python3.10/site-packages/wandb/sdk/lib/sock_client.py", line 151, in _send_message
    self._sendall_with_error_handle(header + data)
  File "/home/qrbao/anaconda3/envs/rllib/lib/python3.10/site-packages/wandb/sdk/lib/sock_client.py", line 130, in _sendall_with_error_handle
    sent = self._sock.send(data)
BrokenPipeError: [Errno 32] Broken pipe
2025-07-03 12:22:09,427 ERROR   ray_print_logs:3300374 [redirect.py:_on_write():664] [no run ID] error in stdout callback
Traceback (most recent call last):
  File "/home/qrbao/anaconda3/envs/rllib/lib/python3.10/site-packages/wandb/sdk/lib/redirect.py", line 662, in _on_write
    cb(written_data)
  File "/home/qrbao/anaconda3/envs/rllib/lib/python3.10/site-packages/wandb/sdk/wandb_run.py", line 2374, in <lambda>
    lambda data: self._console_raw_callback("stdout", data),
  File "/home/qrbao/anaconda3/envs/rllib/lib/python3.10/site-packages/wandb/sdk/wandb_run.py", line 391, in wrapper
    return func(self, *args, **kwargs)
  File "/home/qrbao/anaconda3/envs/rllib/lib/python3.10/site-packages/wandb/sdk/wandb_run.py", line 449, in wrapper_fn
    return func(self, *args, **kwargs)
  File "/home/qrbao/anaconda3/envs/rllib/lib/python3.10/site-packages/wandb/sdk/wandb_run.py", line 1561, in _console_raw_callback
    self._backend.interface.publish_output_raw(name, data)
  File "/home/qrbao/anaconda3/envs/rllib/lib/python3.10/site-packages/wandb/sdk/interface/interface.py", line 772, in publish_output_raw
    self._publish_output_raw(o)
  File "/home/qrbao/anaconda3/envs/rllib/lib/python3.10/site-packages/wandb/sdk/interface/interface_shared.py", line 38, in _publish_output_raw
    self._publish(rec)
  File "/home/qrbao/anaconda3/envs/rllib/lib/python3.10/site-packages/wandb/sdk/interface/interface_sock.py", line 39, in _publish
    self._sock_client.send_record_publish(record)
  File "/home/qrbao/anaconda3/envs/rllib/lib/python3.10/site-packages/wandb/sdk/lib/sock_client.py", line 174, in send_record_publish
    self.send_server_request(server_req)
  File "/home/qrbao/anaconda3/envs/rllib/lib/python3.10/site-packages/wandb/sdk/lib/sock_client.py", line 154, in send_server_request
    self._send_message(msg)
  File "/home/qrbao/anaconda3/envs/rllib/lib/python3.10/site-packages/wandb/sdk/lib/sock_client.py", line 151, in _send_message
    self._sendall_with_error_handle(header + data)
  File "/home/qrbao/anaconda3/envs/rllib/lib/python3.10/site-packages/wandb/sdk/lib/sock_client.py", line 130, in _sendall_with_error_handle
    sent = self._sock.send(data)
BrokenPipeError: [Errno 32] Broken pipe
